Workbook

Sheet CTAS
A2: ENERO | C2: FEBRERO | E2: MARZO | G2: ABRIL | I2: MAYO | K2: JUNIO
A3: 7 | B3: =A5 -> 0 | C3: 7 | D3: =C5 -> 0 | E3: 7 | F3: =E5 -> 0 | G3: 7 | H3: =G5 -> 0 | I3: 7 | J3: =I5 -> 0 | K3: 7 | L3: =K5 -> 0
A4: =COUNTIF(ENERO!$H$15:$H$21,TRUE) -> 0 | B4: =1-A5 -> 1 | C4: =SUM(FEBRERO!$H$15:$H$21) -> 0 | D4: =1-C5 -> 1 | E4: =SUM(MARZO!$H$15:$H$21) -> 0 | F4: =1-E5 -> 1 | G4: =SUM(ABRIL!$H$15:$H$21) -> 0 | H4: =1-G5 -> 1 | I4: =SUM(MAYO!$H$15:$H$21) -> 0 | J4: =1-I5 -> 1 | K4: =SUM(JUNIO!$H$15:$H$21) -> 0 | L4: =1-K5 -> 1
A5: =A4/A3 -> 0 | C5: =C4/C3 -> 0 | E5: =E4/E3 -> 0 | G5: =G4/G3 -> 0 | I5: =I4/I3 -> 0 | K5: =K4/K3 -> 0
A7: JULIO | C7: AGOSTO | E7: SEPTIEMBRE | G7: OCTUBRE | I7: NOVIEMBRE | K7: DICIEMBRE
A8: 7 | B8: =A10 -> 0 | C8: 7 | D8: =C10 -> 0 | E8: 7 | F8: =E10 -> 0 | G8: 7 | H8: =G10 -> 0 | I8: 7 | J8: =I10 -> 0 | K8: 7 | L8: =K10 -> 0
A9: =SUM(JULIO!$H$15:$H$21) -> 0 | B9: =1-A10 -> 1 | C9: =SUM(AGOSTO!$H$15:$H$21) -> 0 | D9: =1-C10 -> 1 | E9: =SUM(SEPTIEMBRE!$H$15:$H$21) -> 0 | F9: =1-E10 -> 1 | G9: =SUM(OCTUBRE!$H$15:$H$21) -> 0 | H9: =1-G10 -> 1 | I9: =SUM(NOVIEMBRE!$H$15:$H$21) -> 0 | J9: =1-I10 -> 1 | K9: =SUM(DICIEMBRE!$H$15:$H$21) -> 0 | L9: =1-K10 -> 1
A10: =A9/A8 -> 0 | C10: =C9/C8 -> 0 | E10: =E9/E8 -> 0 | G10: =G9/G8 -> 0 | I10: =I9/I8 -> 0 | K10: =K9/K8 -> 0

Sheet RESUMEN
H1: RESUMEN FINANCIERO
K4: 2026
F9: ENERO | G9: FEBRERO | H9: MARZO | I9: ABRIL | J9: MAYO | K9: JUNIO | L9: JULIO | M9: AGOSTO | N9: SEPTIEMBRE | O9: OCTUBRE | P9: NOVIEMBRE | Q9: DICIEMBRE | R9: PROMEDIO | S9: TOTAL
D10: INGRESOS | F10: =ENERO!$L$5 -> 10000 | G10: =FEBRERO!$L$5 -> 0 | H10: =MARZO!$L$5 -> 0 | I10: =ABRIL!$L$5 -> 0 | J10: =MAYO!$L$5 -> 0 | K10: =JUNIO!$L$5 -> 0 | L10: =JULIO!$L$5 -> 0 | M10: =AGOSTO!$L$5 -> 0 | N10: =SEPTIEMBRE!$L$5 -> 0 | O10: =OCTUBRE!$L$5 -> 0 | P10: =NOVIEMBRE!$L$5 -> 0 | Q10: =DICIEMBRE!$L$5 -> 0 | R10: =AVERAGEIF(F10:Q11,">0") -> 10000 | S10: =SUM(F10:Q10) -> 10000
D12: GASTOS FIJOS | F12: =ENERO!$H$8 -> 0 | G12: =FEBRERO!$H$8 -> 0 | H12: =MARZO!$H$8 -> 0 | I12: =ABRIL!$H$8 -> 0 | J12: =MAYO!$H$8 -> 0 | K12: =JUNIO!$H$8 -> 0 | L12: =JULIO!$H$8 -> 0 | M12: =AGOSTO!$H$8 -> 0 | N12: =SEPTIEMBRE!$H$8 -> 0 | O12: =OCTUBRE!$H$8 -> 0 | P12: =NOVIEMBRE!$H$8 -> 0 | Q12: =DICIEMBRE!$H$8 -> 0 | R12: =AVERAGEIF(F12:Q13,">0") -> #DIV/0! | S12: =SUM(F12:Q13) -> 0
D14: GASTOS VARIABLES | F14: =ENERO!$I$8 -> 3000 | G14: =FEBRERO!$I$8 -> 0 | H14: =MARZO!$I$8 -> 0 | I14: =ABRIL!$I$8 -> 0 | J14: =MAYO!$I$8 -> 0 | K14: =JUNIO!$I$8 -> 0 | L14: =JULIO!$I$8 -> 0 | M14: =AGOSTO!$I$8 -> 0 | N14: =SEPTIEMBRE!$I$8 -> 0 | O14: =OCTUBRE!$I$8 -> 0 | P14: =NOVIEMBRE!$I$8 -> 0 | Q14: =DICIEMBRE!$I$8 -> 0 | R14: =AVERAGEIF(F14:Q15,">0") -> 3000 | S14: =SUM(F14:Q15) -> 3000
D16: GASTOS TOTALES | F16: =ENERO!$L$8 -> 3000 | G16: =FEBRERO!$L$8 -> 0 | H16: =MARZO!$L$8 -> 0 | I16: =ABRIL!$L$8 -> 0 | J16: =MAYO!$L$8 -> 0 | K16: =JUNIO!$L$8 -> 0 | L16: =JULIO!$L$8 -> 0 | M16: =AGOSTO!$L$8 -> 0 | N16: =SEPTIEMBRE!$L$8 -> 0 | O16: =OCTUBRE!$L$8 -> 0 | P16: =NOVIEMBRE!$L$8 -> 0 | Q16: =DICIEMBRE!$L$8 -> 0 | R16: =AVERAGEIF(F16:Q17,">0") -> 3000 | S16: =SUM(F16:Q17) -> 3000
D18: AHORROS | F18: =ENERO!$J$8 -> 0 | G18: =FEBRERO!$J$8 -> 0 | H18: =MARZO!$J$8 -> 0 | I18: =ABRIL!$J$8 -> 0 | J18: =MAYO!$J$8 -> 0 | K18: =JUNIO!$J$8 -> 0 | L18: =JULIO!$J$8 -> 0 | M18: =AGOSTO!$J$8 -> 0 | N18: =SEPTIEMBRE!$J$8 -> 0 | O18: =OCTUBRE!$J$8 -> 0 | P18: =NOVIEMBRE!$J$8 -> 0 | Q18: =DICIEMBRE!$J$8 -> 0 | R18: =AVERAGEIF(F18:Q19,">0") -> #DIV/0! | S18: =SUM(F18:Q19) -> 0
D20: INVERSIONES | F20: =ENERO!$K$8 -> 0 | G20: =FEBRERO!$K$8 -> 0 | H20: =MARZO!$K$8 -> 0 | I20: =ABRIL!$K$8 -> 0 | J20: =MAYO!$K$8 -> 0 | K20: =JUNIO!$K$8 -> 0 | L20: =JULIO!$K$8 -> 0 | M20: =AGOSTO!$K$8 -> 0 | N20: =SEPTIEMBRE!$K$8 -> 0 | O20: =OCTUBRE!$K$8 -> 0 | P20: =NOVIEMBRE!$K$8 -> 0 | Q20: =DICIEMBRE!$K$8 -> 0 | R20: =AVERAGEIF(F20:Q21,">0") -> #DIV/0! | S20: =SUM(F20:Q21) -> 0
D55: CATEGORIA DE GASTOS | F55: ENERO | G55: FEBRERO | H55: MARZO | I55: ABRIL | J55: MAYO | K55: JUNIO | L55: JULIO | M55: AGOSTO | N55: SEPTIEMBRE | O55: OCTUBRE | P55: NOVIEMBRE | Q55: DICIEMBRE | R55: PROMEDIO | S55: TOTAL
D57: Transporte | F57: =ENERO!$T$15 -> 0 | G57: =FEBRERO!$T15 -> 0 | H57: =MARZO!$T15 -> 0 | I57: =ABRIL!$T15 -> 0 | J57: =MAYO!$T15 -> 0 | K57: =JUNIO!$T15 -> 0 | L57: =JULIO!$T15 -> 0 | M57: =AGOSTO!$T15 -> 0 | N57: =SEPTIEMBRE!$T15 -> 0 | O57: =OCTUBRE!$T15 -> 0 | P57: =NOVIEMBRE!$T15 -> 0 | Q57: =DICIEMBRE!$T15 -> 0 | R57: =AVERAGEIF(F57:Q57,">0") -> #DIV/0! | S57: =SUM(F57:Q57) -> 0
D58: Alimentación | F58: =ENERO!$T$16 -> 0 | G58: =FEBRERO!$T16 -> 0 | H58: =MARZO!$T16 -> 0 | I58: =ABRIL!$T16 -> 0 | J58: =MAYO!$T16 -> 0 | K58: =JUNIO!$T16 -> 0 | L58: =JULIO!$T16 -> 0 | M58: =AGOSTO!$T16 -> 0 | N58: =SEPTIEMBRE!$T16 -> 0 | O58: =OCTUBRE!$T16 -> 0 | P58: =NOVIEMBRE!$T16 -> 0 | Q58: =DICIEMBRE!$T16 -> 0 | R58: =AVERAGEIF(F58:Q58,">0") -> #DIV/0! | S58: =SUM(F58:Q58) -> 0
D59: Restaurantes | F59: =ENERO!$T$17 -> 2500 | G59: =FEBRERO!$T17 -> 0 | H59: =MARZO!$T17 -> 0 | I59: =ABRIL!$T17 -> 0 | J59: =MAYO!$T17 -> 0 | K59: =JUNIO!$T17 -> 0 | L59: =JULIO!$T17 -> 0 | M59: =AGOSTO!$T17 -> 0 | N59: =SEPTIEMBRE!$T17 -> 0 | O59: =OCTUBRE!$T17 -> 0 | P59: =NOVIEMBRE!$T17 -> 0 | Q59: =DICIEMBRE!$T17 -> 0 | R59: =AVERAGEIF(F59:Q59,">0") -> 2500 | S59: =SUM(F59:Q59) -> 2500
D60: Delivery | F60: =ENERO!$T$18 -> 0 | G60: =FEBRERO!$T18 -> 0 | H60: =MARZO!$T18 -> 0 | I60: =ABRIL!$T18 -> 0 | J60: =MAYO!$T18 -> 0 | K60: =JUNIO!$T18 -> 0 | L60: =JULIO!$T18 -> 0 | M60: =AGOSTO!$T18 -> 0 | N60: =SEPTIEMBRE!$T18 -> 0 | O60: =OCTUBRE!$T18 -> 0 | P60: =NOVIEMBRE!$T18 -> 0 | Q60: =DICIEMBRE!$T18 -> 0 | R60: =AVERAGEIF(F60:Q60,">0") -> #DIV/0! | S60: =SUM(F60:Q60) -> 0
D61: Bares | F61: =ENERO!$T$19 -> 0 | G61: =FEBRERO!$T19 -> 0 | H61: =MARZO!$T19 -> 0 | I61: =ABRIL!$T19 -> 0 | J61: =MAYO!$T19 -> 0 | K61: =JUNIO!$T19 -> 0 | L61: =JULIO!$T19 -> 0 | M61: =AGOSTO!$T19 -> 0 | N61: =SEPTIEMBRE!$T19 -> 0 | O61: =OCTUBRE!$T19 -> 0 | P61: =NOVIEMBRE!$T19 -> 0 | Q61: =DICIEMBRE!$T19 -> 0 | R61: =AVERAGEIF(F61:Q61,">0") -> #DIV/0! | S61: =SUM(F61:Q61) -> 0
D62: Ropa | F62: =ENERO!$T$20 -> 500 | G62: =FEBRERO!$T20 -> 0 | H62: =MARZO!$T20 -> 0 | I62: =ABRIL!$T20 -> 0 | J62: =MAYO!$T20 -> 0 | K62: =JUNIO!$T20 -> 0 | L62: =JULIO!$T20 -> 0 | M62: =AGOSTO!$T20 -> 0 | N62: =SEPTIEMBRE!$T20 -> 0 | O62: =OCTUBRE!$T20 -> 0 | P62: =NOVIEMBRE!$T20 -> 0 | Q62: =DICIEMBRE!$T20 -> 0 | R62: =AVERAGEIF(F62:Q62,">0") -> 500 | S62: =SUM(F62:Q62) -> 500
D63: Belleza | F63: =ENERO!$T$21 -> 0 | G63: =FEBRERO!$T21 -> 0 | H63: =MARZO!$T21 -> 0 | I63: =ABRIL!$T21 -> 0 | J63: =MAYO!$T21 -> 0 | K63: =JUNIO!$T21 -> 0 | L63: =JULIO!$T21 -> 0 | M63: =AGOSTO!$T21 -> 0 | N63: =SEPTIEMBRE!$T21 -> 0 | O63: =OCTUBRE!$T21 -> 0 | P63: =NOVIEMBRE!$T21 -> 0 | Q63: =DICIEMBRE!$T21 -> 0 | R63: =AVERAGEIF(F63:Q63,">0") -> #DIV/0! | S63: =SUM(F63:Q63) -> 0
D64: Gasolina | F64: =ENERO!$T$22 -> 0 | G64: =FEBRERO!$T22 -> 0 | H64: =MARZO!$T22 -> 0 | I64: =ABRIL!$T22 -> 0 | J64: =MAYO!$T22 -> 0 | K64: =JUNIO!$T22 -> 0 | L64: =JULIO!$T22 -> 0 | M64: =AGOSTO!$T22 -> 0 | N64: =SEPTIEMBRE!$T22 -> 0 | O64: =OCTUBRE!$T22 -> 0 | P64: =NOVIEMBRE!$T22 -> 0 | Q64: =DICIEMBRE!$T22 -> 0 | R64: =AVERAGEIF(F64:Q64,">0") -> #DIV/0! | S64: =SUM(F64:Q64) -> 0
D65: Hogar | F65: =ENERO!$T$23 -> 0 | G65: =FEBRERO!$T23 -> 0 | H65: =MARZO!$T23 -> 0 | I65: =ABRIL!$T23 -> 0 | J65: =MAYO!$T23 -> 0 | K65: =JUNIO!$T23 -> 0 | L65: =JULIO!$T23 -> 0 | M65: =AGOSTO!$T23 -> 0 | N65: =SEPTIEMBRE!$T23 -> 0 | O65: =OCTUBRE!$T23 -> 0 | P65: =NOVIEMBRE!$T23 -> 0 | Q65: =DICIEMBRE!$T23 -> 0 | R65: =AVERAGEIF(F65:Q65,">0") -> #DIV/0! | S65: =SUM(F65:Q65) -> 0
D66: Tarjeta de crédito | F66: =ENERO!$T$24 -> 0 | G66: =FEBRERO!$T24 -> 0 | H66: =MARZO!$T24 -> 0 | I66: =ABRIL!$T24 -> 0 | J66: =MAYO!$T24 -> 0 | K66: =JUNIO!$T24 -> 0 | L66: =JULIO!$T24 -> 0 | M66: =AGOSTO!$T24 -> 0 | N66: =SEPTIEMBRE!$T24 -> 0 | O66: =OCTUBRE!$T24 -> 0 | P66: =NOVIEMBRE!$T24 -> 0 | Q66: =DICIEMBRE!$T24 -> 0 | R66: =AVERAGEIF(F66:Q66,">0") -> #DIV/0! | S66: =SUM(F66:Q66) -> 0
D67: Ocio | F67: =ENERO!$T$25 -> 0 | G67: =FEBRERO!$T25 -> 0 | H67: =MARZO!$T25 -> 0 | I67: =ABRIL!$T25 -> 0 | J67: =MAYO!$T25 -> 0 | K67: =JUNIO!$T25 -> 0 | L67: =JULIO!$T25 -> 0 | M67: =AGOSTO!$T25 -> 0 | N67: =SEPTIEMBRE!$T25 -> 0 | O67: =OCTUBRE!$T25 -> 0 | P67: =NOVIEMBRE!$T25 -> 0 | Q67: =DICIEMBRE!$T25 -> 0 | R67: =AVERAGEIF(F67:Q67,">0") -> #DIV/0! | S67: =SUM(F67:Q67) -> 0
D68: Pequeñas compras | F68: =ENERO!$T$26 -> 0 | G68: =FEBRERO!$T26 -> 0 | H68: =MARZO!$T26 -> 0 | I68: =ABRIL!$T26 -> 0 | J68: =MAYO!$T26 -> 0 | K68: =JUNIO!$T26 -> 0 | L68: =JULIO!$T26 -> 0 | M68: =AGOSTO!$T26 -> 0 | N68: =SEPTIEMBRE!$T26 -> 0 | O68: =OCTUBRE!$T26 -> 0 | P68: =NOVIEMBRE!$T26 -> 0 | Q68: =DICIEMBRE!$T26 -> 0 | R68: =AVERAGEIF(F68:Q68,">0") -> #DIV/0! | S68: =SUM(F68:Q68) -> 0
D69: Tasas/Impuestos | F69: =ENERO!$T$27 -> 0 | G69: =FEBRERO!$T27 -> 0 | H69: =MARZO!$T27 -> 0 | I69: =ABRIL!$T27 -> 0 | J69: =MAYO!$T27 -> 0 | K69: =JUNIO!$T27 -> 0 | L69: =JULIO!$T27 -> 0 | M69: =AGOSTO!$T27 -> 0 | N69: =SEPTIEMBRE!$T27 -> 0 | O69: =OCTUBRE!$T27 -> 0 | P69: =NOVIEMBRE!$T27 -> 0 | Q69: =DICIEMBRE!$T27 -> 0 | R69: =AVERAGEIF(F69:Q69,">0") -> #DIV/0! | S69: =SUM(F69:Q69) -> 0
D70: Viajes/vacaciones | F70: =ENERO!$T$28 -> 0 | G70: =FEBRERO!$T28 -> 0 | H70: =MARZO!$T28 -> 0 | I70: =ABRIL!$T28 -> 0 | J70: =MAYO!$T28 -> 0 | K70: =JUNIO!$T28 -> 0 | L70: =JULIO!$T28 -> 0 | M70: =AGOSTO!$T28 -> 0 | N70: =SEPTIEMBRE!$T28 -> 0 | O70: =OCTUBRE!$T28 -> 0 | P70: =NOVIEMBRE!$T28 -> 0 | Q70: =DICIEMBRE!$T28 -> 0 | R70: =AVERAGEIF(F70:Q70,">0") -> #DIV/0! | S70: =SUM(F70:Q70) -> 0
D71: Tecnologia | F71: =ENERO!$T$29 -> 0 | G71: =FEBRERO!$T29 -> 0 | H71: =MARZO!$T29 -> 0 | I71: =ABRIL!$T29 -> 0 | J71: =MAYO!$T29 -> 0 | K71: =JUNIO!$T29 -> 0 | L71: =JULIO!$T29 -> 0 | M71: =AGOSTO!$T29 -> 0 | N71: =SEPTIEMBRE!$T29 -> 0 | O71: =OCTUBRE!$T29 -> 0 | P71: =NOVIEMBRE!$T29 -> 0 | Q71: =DICIEMBRE!$T29 -> 0 | R71: =AVERAGEIF(F71:Q71,">0") -> #DIV/0! | S71: =SUM(F71:Q71) -> 0
D72: Reparaciones | F72: =ENERO!$T$30 -> 0 | G72: =FEBRERO!$T30 -> 0 | H72: =MARZO!$T30 -> 0 | I72: =ABRIL!$T30 -> 0 | J72: =MAYO!$T30 -> 0 | K72: =JUNIO!$T30 -> 0 | L72: =JULIO!$T30 -> 0 | M72: =AGOSTO!$T30 -> 0 | N72: =SEPTIEMBRE!$T30 -> 0 | O72: =OCTUBRE!$T30 -> 0 | P72: =NOVIEMBRE!$T30 -> 0 | Q72: =DICIEMBRE!$T30 -> 0 | R72: =AVERAGEIF(F72:Q72,">0") -> #DIV/0! | S72: =SUM(F72:Q72) -> 0
D73: Salud | F73: =ENERO!$T$31 -> 0 | G73: =FEBRERO!$T31 -> 0 | H73: =MARZO!$T31 -> 0 | I73: =ABRIL!$T31 -> 0 | J73: =MAYO!$T31 -> 0 | K73: =JUNIO!$T31 -> 0 | L73: =JULIO!$T31 -> 0 | M73: =AGOSTO!$T31 -> 0 | N73: =SEPTIEMBRE!$T31 -> 0 | O73: =OCTUBRE!$T31 -> 0 | P73: =NOVIEMBRE!$T31 -> 0 | Q73: =DICIEMBRE!$T31 -> 0 | R73: =AVERAGEIF(F73:Q73,">0") -> #DIV/0! | S73: =SUM(F73:Q73) -> 0
D74: Higiene | F74: =ENERO!$T$32 -> 0 | G74: =FEBRERO!$T32 -> 0 | H74: =MARZO!$T32 -> 0 | I74: =ABRIL!$T32 -> 0 | J74: =MAYO!$T32 -> 0 | K74: =JUNIO!$T32 -> 0 | L74: =JULIO!$T32 -> 0 | M74: =AGOSTO!$T32 -> 0 | N74: =SEPTIEMBRE!$T32 -> 0 | O74: =OCTUBRE!$T32 -> 0 | P74: =NOVIEMBRE!$T32 -> 0 | Q74: =DICIEMBRE!$T32 -> 0 | R74: =AVERAGEIF(F74:Q74,">0") -> #DIV/0! | S74: =SUM(F74:Q74) -> 0
D75: Cursos/Fromación/Trabajo | F75: =ENERO!$T$33 -> 0 | G75: =FEBRERO!$T33 -> 0 | H75: =MARZO!$T33 -> 0 | I75: =ABRIL!$T33 -> 0 | J75: =MAYO!$T33 -> 0 | K75: =JUNIO!$T33 -> 0 | L75: =JULIO!$T33 -> 0 | M75: =AGOSTO!$T33 -> 0 | N75: =SEPTIEMBRE!$T33 -> 0 | O75: =OCTUBRE!$T33 -> 0 | P75: =NOVIEMBRE!$T33 -> 0 | Q75: =DICIEMBRE!$T33 -> 0 | R75: =AVERAGEIF(F75:Q75,">0") -> #DIV/0! | S75: =SUM(F75:Q75) -> 0
D76: Mascotas | F76: =ENERO!$T$34 -> 0 | G76: =FEBRERO!$T34 -> 0 | H76: =MARZO!$T34 -> 0 | I76: =ABRIL!$T34 -> 0 | J76: =MAYO!$T34 -> 0 | K76: =JUNIO!$T34 -> 0 | L76: =JULIO!$T34 -> 0 | M76: =AGOSTO!$T34 -> 0 | N76: =SEPTIEMBRE!$T34 -> 0 | O76: =OCTUBRE!$T34 -> 0 | P76: =NOVIEMBRE!$T34 -> 0 | Q76: =DICIEMBRE!$T34 -> 0 | R76: =AVERAGEIF(F76:Q76,">0") -> #DIV/0! | S76: =SUM(F76:Q76) -> 0
D77: Familia | F77: =ENERO!$T$35 -> 0 | G77: =FEBRERO!$T35 -> 0 | H77: =MARZO!$T35 -> 0 | I77: =ABRIL!$T35 -> 0 | J77: =MAYO!$T35 -> 0 | K77: =JUNIO!$T35 -> 0 | L77: =JULIO!$T35 -> 0 | M77: =AGOSTO!$T35 -> 0 | N77: =SEPTIEMBRE!$T35 -> 0 | O77: =OCTUBRE!$T35 -> 0 | P77: =NOVIEMBRE!$T35 -> 0 | Q77: =DICIEMBRE!$T35 -> 0 | R77: =AVERAGEIF(F77:Q77,">0") -> #DIV/0! | S77: =SUM(F77:Q77) -> 0
D78: Otros | F78: =ENERO!$T$36 -> 0 | G78: =FEBRERO!$T36 -> 0 | H78: =MARZO!$T36 -> 0 | I78: =ABRIL!$T36 -> 0 | J78: =MAYO!$T36 -> 0 | K78: =JUNIO!$T36 -> 0 | L78: =JULIO!$T36 -> 0 | M78: =AGOSTO!$T36 -> 0 | N78: =SEPTIEMBRE!$T36 -> 0 | O78: =OCTUBRE!$T36 -> 0 | P78: =NOVIEMBRE!$T36 -> 0 | Q78: =DICIEMBRE!$T36 -> 0 | R78: =AVERAGEIF(F78:Q78,">0") -> #DIV/0! | S78: =SUM(F78:Q78) -> 0
D79: Préstamos | F79: =ENERO!$T$37 -> 0 | G79: =FEBRERO!$T37 -> 0 | H79: =MARZO!$T37 -> 0 | I79: =ABRIL!$T37 -> 0 | J79: =MAYO!$T37 -> 0 | K79: =JUNIO!$T37 -> 0 | L79: =JULIO!$T37 -> 0 | M79: =AGOSTO!$T37 -> 0 | N79: =SEPTIEMBRE!$T37 -> 0 | O79: =OCTUBRE!$T37 -> 0 | P79: =NOVIEMBRE!$T37 -> 0 | Q79: =DICIEMBRE!$T37 -> 0 | R79: =AVERAGEIF(F79:Q79,">0") -> #DIV/0! | S79: =SUM(F79:Q79) -> 0

Sheet ENERO
D2: OBJETIVOS CUMPLIDOS | G2: RESUMEN
D3: =CTAS!B3 -> 0 | N3: ENERO
H4: INGRESOS | J4: SALDO REMANENTE | L4: TOTAL
G5: I. DISPONIBLES | H5: =H37 -> 10000 | J5: =G39 -> 0 | L5: =H5+J5 -> 10000 | S5: DISPONIBLES PARA GASTOS
N6: 2026
H7: FIJOS | I7: VARIABLES | J7: AHORROS | K7: INVERSIÓN | L7: TOTAL | N7: INICIO | Q7: 46023 | S7: INGRESOS DISPONIBLES | U7: GASTOS | W7: RESTO
G8: GASTOS | H8: =M40 -> 0 | I8: =O120 -> 3000 | J8: =H52 -> 0 | K8: =H53 -> 0 | L8: =SUM(H8:K8) -> 3000 | N8: FINAL | Q8: 46053 | S8: =L5 -> 10000 | U8: =L8 -> 3000 | W8: =S8-U8 -> 7000
D12: OBJETIVOS FINANCIEROS DEL MES | J12: GASTOS FIJOS | R12: GASTOS VARIABLES | X12: GASTOS TOTALES
X13: Gastos fijos | Z13: =M40 -> 0
D14: OBJETIVOS | H14: ✔ | J14: CONCEPTO | L14: GASTO ESPERADO | M14: GASTO REAL | N14: METODO DE PAGO | O14: VENCIMIENTO | P14: PAGADO | R14: CATEGORIA | T14: GASTO TOTAL POR CATEGORIA | V14: % DEL TOTAL | X14: Gastos variables | Z14: =O120 -> 3000
H15: FALSE | P15: FALSE | R15: Transporte | T15: =SUMIF($K$59:$L$119,R15,$O$59:$P$119) -> 0 | V15: =T15*1/$T$40 -> 0 | X15: Ahorros | Z15: =H52 -> 0
H16: FALSE | P16: FALSE | R16: Alimentación | T16: =SUMIF($K$59:$L$119,R16,$O$59:$P$119) -> 0 | V16: =T16*1/$T$40 -> 0 | X16: Inversión | Z16: =H53 -> 0
H17: FALSE | P17: FALSE | R17: Restaurantes | T17: =SUMIF($K$59:$L$119,R17,$O$59:$P$119) -> 2500 | V17: =T17*1/$T$40 -> 0.83333333 | X17: TOTAL | Z17: =SUM(Z13:Z16) -> 3000
H18: FALSE | P18: FALSE | R18: Delivery | T18: =SUMIF($K$59:$L$119,R18,$O$59:$P$119) -> 0 | V18: =T18*1/$T$40 -> 0
H19: FALSE | P19: FALSE | R19: Bares | T19: =SUMIF($K$59:$L$119,R19,$O$59:$P$119) -> 0 | V19: =T19*1/$T$40 -> 0
H20: FALSE | P20: FALSE | R20: Ropa | T20: =SUMIF($K$59:$L$119,R20,$O$59:$P$119) -> 500 | V20: =T20*1/$T$40 -> 0.16666667
H21: FALSE | P21: FALSE | R21: Belleza | T21: =SUMIF($K$59:$L$119,R21,$O$59:$P$119) -> 0 | V21: =T21*1/$T$40 -> 0
P22: FALSE | R22: Gasolina | T22: =SUMIF($K$59:$L$119,R22,$O$59:$P$119) -> 0 | V22: =T22*1/$T$40 -> 0
D23: INGRESOS | P23: FALSE | R23: Hogar | T23: =SUMIF($K$59:$L$119,R23,$O$59:$P$119) -> 0 | V23: =T23*1/$T$40 -> 0
P24: FALSE | R24: Tarjeta de crédito | T24: =SUMIF($K$59:$L$119,R24,$O$59:$P$119) -> 0 | V24: =T24*1/$T$40 -> 0
D25: CONCEPTO | G25: CANTIDAD ESPERADA | H25: CANTIDAD RECIBIDA | P25: FALSE | R25: Ocio | T25: =SUMIF($K$59:$L$119,R25,$O$59:$P$119) -> 0 | V25: =T25*1/$T$40 -> 0
H26: 10000 | P26: FALSE | R26: Pequeñas compras | T26: =SUMIF($K$59:$L$119,R26,$O$59:$P$119) -> 0 | V26: =T26*1/$T$40 -> 0 | X26: RESUMEN TIPO DE PAGO
P27: FALSE | R27: Tasas/Impuestos | T27: =SUMIF($K$59:$L$119,R27,$O$59:$P$119) -> 0 | V27: =T27*1/$T$40 -> 0 | X27: Trajeta de débito | Z27: =SUMIF(M59:N119,"Tarjeta de débito",O59:P119)+SUMIF(N15:N39,"Tarjeta de débito",M15:M39) -> 0 | AA27: =Z27*1/$U$8 -> 0
P28: FALSE | R28: Viajes/vacaciones | T28: =SUMIF($K$59:$L$119,R28,$O$59:$P$119) -> 0 | V28: =T28*1/$T$40 -> 0 | X28: Tarjeta de crédito | Z28: =SUMIF(M59:N119,"Tarjeta de crédito",O59:P119)+SUMIF(N15:N39,"Tarjeta de crédito",M15:M39) -> 2500 | AA28: =Z28*1/$U$8 -> 0.83333333
P29: FALSE | R29: Tecnología | T29: =SUMIF($K$59:$L$119,R29,$O$59:$P$119) -> 0 | V29: =T29*1/$T$40 -> 0 | X29: Efectivo | Z29: =SUMIF(M59:N119,"Efectivo",O59:P119)+SUMIF(N15:N39,"Efectivo",M15:M39) -> 500 | AA29: =Z29*1/$U$8 -> 0.16666667
P30: FALSE | R30: Reparaciones | T30: =SUMIF($K$59:$L$119,R30,$O$59:$P$119) -> 0 | V30: =T30*1/$T$40 -> 0 | X30: Transferencia | Z30: =SUMIF(M59:N119,"Transferencia",O59:P119)+SUMIF(N15:N39,"Transferencia",M15:M39) -> 0 | AA30: =Z30*1/$U$8 -> 0
P31: FALSE | R31: Salud | T31: =SUMIF($K$59:$L$119,R31,$O$59:$P$119) -> 0 | V31: =T31*1/$T$40 -> 0
P32: FALSE | R32: Higiene | T32: =SUMIF($K$59:$L$119,R32,$O$59:$P$119) -> 0 | V32: =T32*1/$T$40 -> 0 | X32: CONTROL DE DINERO
P33: FALSE | R33: Cursos/Fromación/Trabajo | T33: =SUMIF($K$59:$L$119,R33,$O$59:$P$119) -> 0 | V33: =T33*1/$T$40 -> 0
P34: FALSE | R34: Mascotas | T34: =SUMIF($K$59:$L$119,R34,$O$59:$P$119) -> 0 | V34: =T34*1/$T$40 -> 0 | X34: VIRTUAL (LO QUE ANOTASTE)
P35: FALSE | R35: Familia | T35: =SUMIF($K$59:$L$119,R35,$O$59:$P$119) -> 0 | V35: =T35*1/$T$40 -> 0 | X35: Resto | Z35: =W8 -> 7000
D36: TOTAL INGRESOS | F36: ING ESPERADOS | H36: =SUM(G26:G35) -> 0 | P36: FALSE | R36: Otros | T36: =SUMIF($K$59:$L$119,R36,$O$59:$P$119) -> 0 | V36: =T36*1/$T$40 -> 0 | X36: REAL
F37: ING REALES | H37: =SUM(H26:H35) -> 10000 | P37: FALSE | R37: Préstamos | T37: =SUMIF($K$59:$L$119,R37,$O$59:$P$119) -> 0 | V37: =T37*1/$T$40 -> 0 | X37: Tarjetas de débito
P38: FALSE | X38: Efectivo
D39: SALDO REMANENTE (MES ANTERIOR) | P39: FALSE | X39: DIFERENCIA | Z39: =(Z38+Z37)-Z35 -> -7000
J40: TOTAL | L40: =SUM(L15:L39) -> 0 | M40: =SUM(M15:M39) -> 0 | R40: TOTAL | T40: =SUM(T15:U39) -> 3000 | Z40: =IF(Z39<0,"Te falta dinero o anotar algo", "Te sobra dinero o anotar algo") -> Te falta dinero o anotar algo
D42: AHORRO E INVERSIÓN | J42: TOTAL GASTOS (FIJOS + VARIABLES) | S42: =M40+O120 -> 3000
D44: CONCEPTO | G44: CATEGORÍA | H44: CANTIDAD
D52: TOTAL AHORROS | H52: =SUMIF(G45:G51, "Ahorro", H45:H51) -> 0
D53: TOTAL INVERSIÓN | H53: =SUMIF(G45:G51, "Inversión", H45:H51) -> 0
...

Sheet FEBRERO
D2: OBJETIVOS CUMPLIDOS | G2: RESUMEN
D3: =CTAS!D3 -> 0 | N3: FEBRERO
H4: INGRESOS | J4: SALDO REMANENTE | L4: TOTAL
G5: I. DISPONIBLES | H5: =H37 -> 0 | J5: =G39 -> 0 | L5: =H5+J5 -> 0 | S5: DISPONIBLES PARA GASTOS
N6: 2026
H7: FIJOS | I7: VARIABLES | J7: AHORROS | K7: INVERSIÓN | L7: TOTAL | N7: INICIO | Q7: 46054 | S7: INGRESOS DISPONIBLES | U7: GASTOS | W7: RESTO
G8: GASTOS | H8: =M40 -> 0 | I8: =O120 -> 0 | J8: =H52 -> 0 | K8: =H53 -> 0 | L8: =SUM(H8:K8) -> 0 | N8: FINAL | Q8: 46081 | S8: =L5 -> 0 | U8: =L8 -> 0 | W8: =S8-U8 -> 0
D12: OBJETIVOS FINANCIEROS DEL MES | J12: GASTOS FIJOS | R12: GASTOS VARIABLES | X12: GASTOS TOTALES
X13: Gastos fijos | Z13: =M40 -> 0
D14: CONCEPTO | H14: ✔ | J14: CONCEPTO | L14: GASTO ESPERADO | M14: GASTO REAL | N14: METODO DE PAGO | O14: FECHA DE COBRO | P14: PAGADO | R14: CATEGORIA | T14: GASTO TOTAL POR CATEGORIA | V14: % DEL TOTAL | X14: Gastos variables | Z14: =O120 -> 0
H15: 0 | P15: 0 | R15: Transporte | T15: =SUMIF($K$59:$L$119,R15,$O$59:$P$119) -> 0 | V15: =T15*1/$T$40 -> #DIV/0! | X15: Ahorros | Z15: =H52 -> 0
H16: 0 | P16: 0 | R16: Alimentación | T16: =SUMIF($K$59:$L$119,R16,$O$59:$P$119) -> 0 | V16: =T16*1/$T$40 -> #DIV/0! | X16: Inversión | Z16: =H53 -> 0
H17: 0 | P17: 0 | R17: Restaurantes | T17: =SUMIF($K$59:$L$119,R17,$O$59:$P$119) -> 0 | V17: =T17*1/$T$40 -> #DIV/0! | X17: TOTAL | Z17: =SUM(Z13:Z16) -> 0
H18: 0 | P18: 0 | R18: Delivery | T18: =SUMIF($K$59:$L$119,R18,$O$59:$P$119) -> 0 | V18: =T18*1/$T$40 -> #DIV/0!
H19: 0 | P19: 0 | R19: Bares | T19: =SUMIF($K$59:$L$119,R19,$O$59:$P$119) -> 0 | V19: =T19*1/$T$40 -> #DIV/0!
H20: 0 | P20: 0 | R20: Ropa | T20: =SUMIF($K$59:$L$119,R20,$O$59:$P$119) -> 0 | V20: =T20*1/$T$40 -> #DIV/0!
H21: 0 | P21: 0 | R21: Belleza | T21: =SUMIF($K$59:$L$119,R21,$O$59:$P$119) -> 0 | V21: =T21*1/$T$40 -> #DIV/0!
P22: 0 | R22: Gasolina | T22: =SUMIF($K$59:$L$119,R22,$O$59:$P$119) -> 0 | V22: =T22*1/$T$40 -> #DIV/0!
D23: INGRESOS | P23: 0 | R23: Hogar | T23: =SUMIF($K$59:$L$119,R23,$O$59:$P$119) -> 0 | V23: =T23*1/$T$40 -> #DIV/0!
P24: 0 | R24: Tarjeta de crédito | T24: =SUMIF($K$59:$L$119,R24,$O$59:$P$119) -> 0 | V24: =T24*1/$T$40 -> #DIV/0!
D25: CONCEPTO | G25: CANTIDAD ESPERADA | H25: CANTIDAD RECIBIDA | P25: 0 | R25: Ocio | T25: =SUMIF($K$59:$L$119,R25,$O$59:$P$119) -> 0 | V25: =T25*1/$T$40 -> #DIV/0!
P26: 0 | R26: Pequeñas compras | T26: =SUMIF($K$59:$L$119,R26,$O$59:$P$119) -> 0 | V26: =T26*1/$T$40 -> #DIV/0! | X26: RESUMEN TIPO DE PAGO
P27: 0 | R27: Tasas/Impuestos | T27: =SUMIF($K$59:$L$119,R27,$O$59:$P$119) -> 0 | V27: =T27*1/$T$40 -> #DIV/0! | X27: Trajeta de débito | Z27: =SUMIF(M59:N119,"Tarjeta de débito",O59:P119)+SUMIF(N15:N39,"Tarjeta de débito",M15:M39) -> 0 | AA27: =Z27*1/$U$8 -> #DIV/0!
P28: 0 | R28: Viajes/vacaciones | T28: =SUMIF($K$59:$L$119,R28,$O$59:$P$119) -> 0 | V28: =T28*1/$T$40 -> #DIV/0! | X28: Tarjeta de crédito | Z28: =SUMIF(M59:N119,"Tarjeta de crédito",O59:P119)+SUMIF(N15:N39,"Tarjeta de crédito",M15:M39) -> 0 | AA28: =Z28*1/$U$8 -> #DIV/0!
P29: 0 | R29: Tecnología | T29: =SUMIF($K$59:$L$119,R29,$O$59:$P$119) -> 0 | V29: =T29*1/$T$40 -> #DIV/0! | X29: Efectivo | Z29: =SUMIF(M59:N119,"Efectivo",O59:P119)+SUMIF(N15:N39,"Efectivo",M15:M39) -> 0 | AA29: =Z29*1/$U$8 -> #DIV/0!
P30: 0 | R30: Reparaciones | T30: =SUMIF($K$59:$L$119,R30,$O$59:$P$119) -> 0 | V30: =T30*1/$T$40 -> #DIV/0! | X30: Transferencia | Z30: =SUMIF(M59:N119,"Transferencia",O59:P119)+SUMIF(N15:N39,"Transferencia",M15:M39) -> 0 | AA30: =Z30*1/$U$8 -> #DIV/0!
P31: 0 | R31: Salud | T31: =SUMIF($K$59:$L$119,R31,$O$59:$P$119) -> 0 | V31: =T31*1/$T$40 -> #DIV/0!
P32: 0 | R32: Higiene | T32: =SUMIF($K$59:$L$119,R32,$O$59:$P$119) -> 0 | V32: =T32*1/$T$40 -> #DIV/0! | X32: CONTROL DE DINERO
P33: 0 | R33: Cursos/Fromación/Trabajo | T33: =SUMIF($K$59:$L$119,R33,$O$59:$P$119) -> 0 | V33: =T33*1/$T$40 -> #DIV/0!
P34: 0 | R34: Mascotas | T34: =SUMIF($K$59:$L$119,R34,$O$59:$P$119) -> 0 | V34: =T34*1/$T$40 -> #DIV/0! | X34: VIRTUAL (LO QUE ANOTASTE)
P35: 0 | R35: Familia | T35: =SUMIF($K$59:$L$119,R35,$O$59:$P$119) -> 0 | V35: =T35*1/$T$40 -> #DIV/0! | X35: Resto | Z35: =W8 -> 0
D36: TOTAL INGRESOS | F36: ING ESPERADOS | H36: =SUM(G26:G35) -> 0 | P36: 0 | R36: Otros | T36: =SUMIF($K$59:$L$119,R36,$O$59:$P$119) -> 0 | V36: =T36*1/$T$40 -> #DIV/0! | X36: REAL
F37: ING REALES | H37: =SUM(H26:H35) -> 0 | P37: 0 | R37: Préstamos | T37: =SUMIF($K$59:$L$119,R37,$O$59:$P$119) -> 0 | V37: =T37*1/$T$40 -> #DIV/0! | X37: Tarjetas de débito
P38: 0 | X38: Efectivo
D39: SALDO REMANENTE (MES ANTERIOR) | P39: 0 | X39: DIFERENCIA | Z39: =(Z38+Z37)-Z35 -> 0
J40: TOTAL | L40: =SUM(L15:L39) -> 0 | M40: =SUM(M15:M39) -> 0 | R40: TOTAL | T40: =SUM(T15:U39) -> 0 | Z40: =IF(Z39<0,"Te falta dinero o anotar algo", "Te sobra dinero o anotar algo") -> Te sobra dinero o anotar algo
D42: AHORRO E INVERSIÓN | J42: TOTAL GASTOS (FIJOS + VARIABLES) | S42: =M40+O120 -> 0
D44: CONCEPTO | G44: CATEGORÍA | H44: CANTIDAD
D52: TOTAL AHORROS | H52: =SUMIF(G45:G51, "Ahorro", H45:H51) -> 0
D53: TOTAL INVERSIÓN | H53: =SUMIF(G45:G51, "Inversión", H45:H51) -> 0
...

Sheet MARZO
D2: OBJETIVOS CUMPLIDOS | G2: RESUMEN
D3: =CTAS!F3 -> 0 | N3: MARZO
H4: INGRESOS | J4: SALDO REMANENTE | L4: TOTAL
G5: I. DISPONIBLES | H5: =H37 -> 0 | J5: =G39 -> 0 | L5: =H5+J5 -> 0 | S5: DISPONIBLES PARA GASTOS
N6: 2026
H7: FIJOS | I7: VARIABLES | J7: AHORROS | K7: INVERSIÓN | L7: TOTAL | N7: INICIO | Q7: 46082 | S7: INGRESOS DISPONIBLES | U7: GASTOS | W7: RESTO
G8: GASTOS | H8: =M40 -> 0 | I8: =O120 -> 0 | J8: =H52 -> 0 | K8: =H53 -> 0 | L8: =SUM(H8:K8) -> 0 | N8: FINAL | Q8: 46112 | S8: =L5 -> 0 | U8: =L8 -> 0 | W8: =S8-U8 -> 0
D12: OBJETIVOS FINANCIEROS DEL MES | J12: GASTOS FIJOS | R12: GASTOS VARIABLES | X12: GASTOS TOTALES
X13: Gastos fijos | Z13: =M40 -> 0
D14: CONCEPTO | H14: ✔ | J14: CONCEPTO | L14: GASTO ESPERADO | M14: GASTO REAL | N14: METODO DE PAGO | O14: FECHA DE COBRO | P14: PAGADO | R14: CATEGORIA | T14: GASTO TOTAL POR CATEGORIA | V14: % DEL TOTAL | X14: Gastos variables | Z14: =O120 -> 0
H15: 0 | P15: 0 | R15: Transporte | T15: =SUMIF($K$59:$L$119,R15,$O$59:$P$119) -> 0 | V15: =T15*1/$T$40 -> #DIV/0! | X15: Ahorros | Z15: =H52 -> 0
H16: 0 | P16: 0 | R16: Alimentación | T16: =SUMIF($K$59:$L$119,R16,$O$59:$P$119) -> 0 | V16: =T16*1/$T$40 -> #DIV/0! | X16: Inversión | Z16: =H53 -> 0
H17: 0 | P17: 0 | R17: Restaurantes | T17: =SUMIF($K$59:$L$119,R17,$O$59:$P$119) -> 0 | V17: =T17*1/$T$40 -> #DIV/0! | X17: TOTAL | Z17: =SUM(Z13:Z16) -> 0
H18: 0 | P18: 0 | R18: Delivery | T18: =SUMIF($K$59:$L$119,R18,$O$59:$P$119) -> 0 | V18: =T18*1/$T$40 -> #DIV/0!
H19: 0 | P19: 0 | R19: Bares | T19: =SUMIF($K$59:$L$119,R19,$O$59:$P$119) -> 0 | V19: =T19*1/$T$40 -> #DIV/0!
H20: 0 | P20: 0 | R20: Ropa | T20: =SUMIF($K$59:$L$119,R20,$O$59:$P$119) -> 0 | V20: =T20*1/$T$40 -> #DIV/0!
H21: 0 | P21: 0 | R21: Belleza | T21: =SUMIF($K$59:$L$119,R21,$O$59:$P$119) -> 0 | V21: =T21*1/$T$40 -> #DIV/0!
P22: 0 | R22: Gasolina | T22: =SUMIF($K$59:$L$119,R22,$O$59:$P$119) -> 0 | V22: =T22*1/$T$40 -> #DIV/0!
D23: INGRESOS | P23: 0 | R23: Hogar | T23: =SUMIF($K$59:$L$119,R23,$O$59:$P$119) -> 0 | V23: =T23*1/$T$40 -> #DIV/0!
P24: 0 | R24: Tarjeta de crédito | T24: =SUMIF($K$59:$L$119,R24,$O$59:$P$119) -> 0 | V24: =T24*1/$T$40 -> #DIV/0!
D25: CONCEPTO | G25: CANTIDAD ESPERADA | H25: CANTIDAD RECIBIDA | P25: 0 | R25: Ocio | T25: =SUMIF($K$59:$L$119,R25,$O$59:$P$119) -> 0 | V25: =T25*1/$T$40 -> #DIV/0!
P26: 0 | R26: Pequeñas compras | T26: =SUMIF($K$59:$L$119,R26,$O$59:$P$119) -> 0 | V26: =T26*1/$T$40 -> #DIV/0! | X26: RESUMEN TIPO DE PAGO
P27: 0 | R27: Tasas/Impuestos | T27: =SUMIF($K$59:$L$119,R27,$O$59:$P$119) -> 0 | V27: =T27*1/$T$40 -> #DIV/0! | X27: Trajeta de débito | Z27: =SUMIF(M59:N119,"Tarjeta de débito",O59:P119)+SUMIF(N15:N39,"Tarjeta de débito",M15:M39) -> 0 | AA27: =Z27*1/$U$8 -> #DIV/0!
P28: 0 | R28: Viajes/vacaciones | T28: =SUMIF($K$59:$L$119,R28,$O$59:$P$119) -> 0 | V28: =T28*1/$T$40 -> #DIV/0! | X28: Tarjeta de crédito | Z28: =SUMIF(M59:N119,"Tarjeta de crédito",O59:P119)+SUMIF(N15:N39,"Tarjeta de crédito",M15:M39) -> 0 | AA28: =Z28*1/$U$8 -> #DIV/0!
P29: 0 | R29: Tecnología | T29: =SUMIF($K$59:$L$119,R29,$O$59:$P$119) -> 0 | V29: =T29*1/$T$40 -> #DIV/0! | X29: Efectivo | Z29: =SUMIF(M59:N119,"Efectivo",O59:P119)+SUMIF(N15:N39,"Efectivo",M15:M39) -> 0 | AA29: =Z29*1/$U$8 -> #DIV/0!
P30: 0 | R30: Reparaciones | T30: =SUMIF($K$59:$L$119,R30,$O$59:$P$119) -> 0 | V30: =T30*1/$T$40 -> #DIV/0! | X30: Transferencia | Z30: =SUMIF(M59:N119,"Transferencia",O59:P119)+SUMIF(N15:N39,"Transferencia",M15:M39) -> 0 | AA30: =Z30*1/$U$8 -> #DIV/0!
P31: 0 | R31: Salud | T31: =SUMIF($K$59:$L$119,R31,$O$59:$P$119) -> 0 | V31: =T31*1/$T$40 -> #DIV/0!
P32: 0 | R32: Higiene | T32: =SUMIF($K$59:$L$119,R32,$O$59:$P$119) -> 0 | V32: =T32*1/$T$40 -> #DIV/0! | X32: CONTROL DE DINERO
P33: 0 | R33: Cursos/Fromación/Trabajo | T33: =SUMIF($K$59:$L$119,R33,$O$59:$P$119) -> 0 | V33: =T33*1/$T$40 -> #DIV/0!
P34: 0 | R34: Mascotas | T34: =SUMIF($K$59:$L$119,R34,$O$59:$P$119) -> 0 | V34: =T34*1/$T$40 -> #DIV/0! | X34: VIRTUAL (LO QUE ANOTASTE)
P35: 0 | R35: Familia | T35: =SUMIF($K$59:$L$119,R35,$O$59:$P$119) -> 0 | V35: =T35*1/$T$40 -> #DIV/0! | X35: Resto | Z35: =W8 -> 0
D36: TOTAL INGRESOS | F36: ING ESPERADOS | H36: =SUM(G26:G35) -> 0 | P36: 0 | R36: Otros | T36: =SUMIF($K$59:$L$119,R36,$O$59:$P$119) -> 0 | V36: =T36*1/$T$40 -> #DIV/0! | X36: REAL
F37: ING REALES | H37: =SUM(H26:H35) -> 0 | P37: 0 | R37: Préstamos | T37: =SUMIF($K$59:$L$119,R37,$O$59:$P$119) -> 0 | V37: =T37*1/$T$40 -> #DIV/0! | X37: Tarjetas de débito
P38: 0 | X38: Efectivo
D39: SALDO REMANENTE (MES ANTERIOR) | P39: 0 | X39: DIFERENCIA | Z39: =(Z38+Z37)-Z35 -> 0
J40: TOTAL | L40: =SUM(L15:L39) -> 0 | M40: =SUM(M15:M39) -> 0 | R40: TOTAL | T40: =SUM(T15:U39) -> 0 | Z40: =IF(Z39<0,"Te falta dinero o anotar algo", "Te sobra dinero o anotar algo") -> Te sobra dinero o anotar algo
D42: AHORRO E INVERSIÓN | J42: TOTAL GASTOS (FIJOS + VARIABLES) | S42: =M40+O120 -> 0
D44: CONCEPTO | G44: CATEGORÍA | H44: CANTIDAD
D52: TOTAL AHORROS | H52: =SUMIF(G45:G51, "Ahorro", H45:H51) -> 0
D53: TOTAL INVERSIÓN | H53: =SUMIF(G45:G51, "Inversión", H45:H51) -> 0
...

Sheet ABRIL
D2: OBJETIVOS CUMPLIDOS | G2: RESUMEN
D3: =CTAS!H3 -> 0 | N3: ABRIL
H4: INGRESOS | J4: SALDO REMANENTE | L4: TOTAL
G5: I. DISPONIBLES | H5: =H37 -> 0 | J5: =G39 -> 0 | L5: =H5+J5 -> 0 | S5: DISPONIBLES PARA GASTOS
N6: 2026
H7: FIJOS | I7: VARIABLES | J7: AHORROS | K7: INVERSIÓN | L7: TOTAL | N7: INICIO | Q7: 46113 | S7: INGRESOS DISPONIBLES | U7: GASTOS | W7: RESTO
G8: GASTOS | H8: =M40 -> 0 | I8: =O120 -> 0 | J8: =H52 -> 0 | K8: =H53 -> 0 | L8: =SUM(H8:K8) -> 0 | N8: FINAL | Q8: 46142 | S8: =L5 -> 0 | U8: =L8 -> 0 | W8: =S8-U8 -> 0
D12: OBJETIVOS FINANCIEROS DEL MES | J12: GASTOS FIJOS | R12: GASTOS VARIABLES | X12: GASTOS TOTALES
X13: Gastos fijos | Z13: =M40 -> 0
D14: CONCEPTO | H14: ✔ | J14: CONCEPTO | L14: GASTO ESPERADO | M14: GASTO REAL | N14: METODO DE PAGO | O14: FECHA DE COBRO | P14: PAGADO | R14: CATEGORIA | T14: GASTO TOTAL POR CATEGORIA | V14: % DEL TOTAL | X14: Gastos variables | Z14: =O120 -> 0
H15: 0 | P15: 0 | R15: Transporte | T15: =SUMIF($K$59:$L$119,R15,$O$59:$P$119) -> 0 | V15: =T15*1/$T$40 -> #DIV/0! | X15: Ahorros | Z15: =H52 -> 0
H16: 0 | P16: 0 | R16: Alimentación | T16: =SUMIF($K$59:$L$119,R16,$O$59:$P$119) -> 0 | V16: =T16*1/$T$40 -> #DIV/0! | X16: Inversión | Z16: =H53 -> 0
H17: 0 | P17: 0 | R17: Restaurantes | T17: =SUMIF($K$59:$L$119,R17,$O$59:$P$119) -> 0 | V17: =T17*1/$T$40 -> #DIV/0! | X17: TOTAL | Z17: =SUM(Z13:Z16) -> 0
H18: 0 | P18: 0 | R18: Delivery | T18: =SUMIF($K$59:$L$119,R18,$O$59:$P$119) -> 0 | V18: =T18*1/$T$40 -> #DIV/0!
H19: 0 | P19: 0 | R19: Bares | T19: =SUMIF($K$59:$L$119,R19,$O$59:$P$119) -> 0 | V19: =T19*1/$T$40 -> #DIV/0!
H20: 0 | P20: 0 | R20: Ropa | T20: =SUMIF($K$59:$L$119,R20,$O$59:$P$119) -> 0 | V20: =T20*1/$T$40 -> #DIV/0!
H21: 0 | P21: 0 | R21: Belleza | T21: =SUMIF($K$59:$L$119,R21,$O$59:$P$119) -> 0 | V21: =T21*1/$T$40 -> #DIV/0!
P22: 0 | R22: Gasolina | T22: =SUMIF($K$59:$L$119,R22,$O$59:$P$119) -> 0 | V22: =T22*1/$T$40 -> #DIV/0!
D23: INGRESOS | P23: 0 | R23: Hogar | T23: =SUMIF($K$59:$L$119,R23,$O$59:$P$119) -> 0 | V23: =T23*1/$T$40 -> #DIV/0!
P24: 0 | R24: Tarjeta de crédito | T24: =SUMIF($K$59:$L$119,R24,$O$59:$P$119) -> 0 | V24: =T24*1/$T$40 -> #DIV/0!
D25: CONCEPTO | G25: CANTIDAD ESPERADA | H25: CANTIDAD RECIBIDA | P25: 0 | R25: Ocio | T25: =SUMIF($K$59:$L$119,R25,$O$59:$P$119) -> 0 | V25: =T25*1/$T$40 -> #DIV/0!
P26: 0 | R26: Pequeñas compras | T26: =SUMIF($K$59:$L$119,R26,$O$59:$P$119) -> 0 | V26: =T26*1/$T$40 -> #DIV/0! | X26: RESUMEN TIPO DE PAGO
P27: 0 | R27: Tasas/Impuestos | T27: =SUMIF($K$59:$L$119,R27,$O$59:$P$119) -> 0 | V27: =T27*1/$T$40 -> #DIV/0! | X27: Trajeta de débito | Z27: =SUMIF(M59:N119,"Tarjeta de débito",O59:P119)+SUMIF(N15:N39,"Tarjeta de débito",M15:M39) -> 0 | AA27: =Z27*1/$U$8 -> #DIV/0!
P28: 0 | R28: Viajes/vacaciones | T28: =SUMIF($K$59:$L$119,R28,$O$59:$P$119) -> 0 | V28: =T28*1/$T$40 -> #DIV/0! | X28: Tarjeta de crédito | Z28: =SUMIF(M59:N119,"Tarjeta de crédito",O59:P119)+SUMIF(N15:N39,"Tarjeta de crédito",M15:M39) -> 0 | AA28: =Z28*1/$U$8 -> #DIV/0!
P29: 0 | R29: Tecnología | T29: =SUMIF($K$59:$L$119,R29,$O$59:$P$119) -> 0 | V29: =T29*1/$T$40 -> #DIV/0! | X29: Efectivo | Z29: =SUMIF(M59:N119,"Efectivo",O59:P119)+SUMIF(N15:N39,"Efectivo",M15:M39) -> 0 | AA29: =Z29*1/$U$8 -> #DIV/0!
P30: 0 | R30: Reparaciones | T30: =SUMIF($K$59:$L$119,R30,$O$59:$P$119) -> 0 | V30: =T30*1/$T$40 -> #DIV/0! | X30: Transferencia | Z30: =SUMIF(M59:N119,"Transferencia",O59:P119)+SUMIF(N15:N39,"Transferencia",M15:M39) -> 0 | AA30: =Z30*1/$U$8 -> #DIV/0!
P31: 0 | R31: Salud | T31: =SUMIF($K$59:$L$119,R31,$O$59:$P$119) -> 0 | V31: =T31*1/$T$40 -> #DIV/0!
P32: 0 | R32: Higiene | T32: =SUMIF($K$59:$L$119,R32,$O$59:$P$119) -> 0 | V32: =T32*1/$T$40 -> #DIV/0! | X32: CONTROL DE DINERO
P33: 0 | R33: Cursos/Fromación/Trabajo | T33: =SUMIF($K$59:$L$119,R33,$O$59:$P$119) -> 0 | V33: =T33*1/$T$40 -> #DIV/0!
P34: 0 | R34: Mascotas | T34: =SUMIF($K$59:$L$119,R34,$O$59:$P$119) -> 0 | V34: =T34*1/$T$40 -> #DIV/0! | X34: VIRTUAL (LO QUE ANOTASTE)
P35: 0 | R35: Familia | T35: =SUMIF($K$59:$L$119,R35,$O$59:$P$119) -> 0 | V35: =T35*1/$T$40 -> #DIV/0! | X35: Resto | Z35: =W8 -> 0
D36: TOTAL INGRESOS | F36: ING ESPERADOS | H36: =SUM(G26:G35) -> 0 | P36: 0 | R36: Otros | T36: =SUMIF($K$59:$L$119,R36,$O$59:$P$119) -> 0 | V36: =T36*1/$T$40 -> #DIV/0! | X36: REAL
F37: ING REALES | H37: =SUM(H26:H35) -> 0 | P37: 0 | R37: Préstamos | T37: =SUMIF($K$59:$L$119,R37,$O$59:$P$119) -> 0 | V37: =T37*1/$T$40 -> #DIV/0! | X37: Tarjetas de débito
P38: 0 | X38: Efectivo
D39: SALDO REMANENTE (MES ANTERIOR) | P39: 0 | X39: DIFERENCIA | Z39: =(Z38+Z37)-Z35 -> 0
J40: TOTAL | L40: =SUM(L15:L39) -> 0 | M40: =SUM(M15:M39) -> 0 | R40: TOTAL | T40: =SUM(T15:U39) -> 0 | Z40: =IF(Z39<0,"Te falta dinero o anotar algo", "Te sobra dinero o anotar algo") -> Te sobra dinero o anotar algo
D42: AHORRO E INVERSIÓN | J42: TOTAL GASTOS (FIJOS + VARIABLES) | S42: =M40+O120 -> 0
D44: CONCEPTO | G44: CATEGORÍA | H44: CANTIDAD
D52: TOTAL AHORROS | H52: =SUMIF(G45:G51, "Ahorro", H45:H51) -> 0
D53: TOTAL INVERSIÓN | H53: =SUMIF(G45:G51, "Inversión", H45:H51) -> 0
...

Sheet MAYO
D2: OBJETIVOS CUMPLIDOS | G2: RESUMEN
D3: =CTAS!J3 -> 0 | N3: MAYO
H4: INGRESOS | J4: SALDO REMANENTE | L4: TOTAL
G5: I. DISPONIBLES | H5: =H37 -> 0 | J5: =G39 -> 0 | L5: =H5+J5 -> 0 | S5: DISPONIBLES PARA GASTOS
N6: 2026
H7: FIJOS | I7: VARIABLES | J7: AHORROS | K7: INVERSIÓN | L7: TOTAL | N7: INICIO | Q7: 46143 | S7: INGRESOS DISPONIBLES | U7: GASTOS | W7: RESTO
G8: GASTOS | H8: =M40 -> 0 | I8: =O120 -> 0 | J8: =H52 -> 0 | K8: =H53 -> 0 | L8: =SUM(H8:K8) -> 0 | N8: FINAL | Q8: 46173 | S8: =L5 -> 0 | U8: =L8 -> 0 | W8: =S8-U8 -> 0
D12: OBJETIVOS FINANCIEROS DEL MES | J12: GASTOS FIJOS | R12: GASTOS VARIABLES | X12: GASTOS TOTALES
X13: Gastos fijos | Z13: =M40 -> 0
D14: CONCEPTO | H14: ✔ | J14: CONCEPTO | L14: GASTO ESPERADO | M14: GASTO REAL | N14: METODO DE PAGO | O14: FECHA DE COBRO | P14: PAGADO | R14: CATEGORIA | T14: GASTO TOTAL POR CATEGORIA | V14: % DEL TOTAL | X14: Gastos variables | Z14: =O120 -> 0
H15: 0 | P15: 0 | R15: Transporte | T15: =SUMIF($K$59:$L$119,R15,$O$59:$P$119) -> 0 | V15: =T15*1/$T$40 -> #DIV/0! | X15: Ahorros | Z15: =H52 -> 0
H16: 0 | P16: 0 | R16: Alimentación | T16: =SUMIF($K$59:$L$119,R16,$O$59:$P$119) -> 0 | V16: =T16*1/$T$40 -> #DIV/0! | X16: Inversión | Z16: =H53 -> 0
H17: 0 | P17: 0 | R17: Restaurantes | T17: =SUMIF($K$59:$L$119,R17,$O$59:$P$119) -> 0 | V17: =T17*1/$T$40 -> #DIV/0! | X17: TOTAL | Z17: =SUM(Z13:Z16) -> 0
H18: 0 | P18: 0 | R18: Delivery | T18: =SUMIF($K$59:$L$119,R18,$O$59:$P$119) -> 0 | V18: =T18*1/$T$40 -> #DIV/0!
H19: 0 | P19: 0 | R19: Bares | T19: =SUMIF($K$59:$L$119,R19,$O$59:$P$119) -> 0 | V19: =T19*1/$T$40 -> #DIV/0!
H20: 0 | P20: 0 | R20: Ropa | T20: =SUMIF($K$59:$L$119,R20,$O$59:$P$119) -> 0 | V20: =T20*1/$T$40 -> #DIV/0!
H21: 0 | P21: 0 | R21: Belleza | T21: =SUMIF($K$59:$L$119,R21,$O$59:$P$119) -> 0 | V21: =T21*1/$T$40 -> #DIV/0!
P22: 0 | R22: Gasolina | T22: =SUMIF($K$59:$L$119,R22,$O$59:$P$119) -> 0 | V22: =T22*1/$T$40 -> #DIV/0!
D23: INGRESOS | P23: 0 | R23: Hogar | T23: =SUMIF($K$59:$L$119,R23,$O$59:$P$119) -> 0 | V23: =T23*1/$T$40 -> #DIV/0!
P24: 0 | R24: Tarjeta de crédito | T24: =SUMIF($K$59:$L$119,R24,$O$59:$P$119) -> 0 | V24: =T24*1/$T$40 -> #DIV/0!
D25: CONCEPTO | G25: CANTIDAD ESPERADA | H25: CANTIDAD RECIBIDA | P25: 0 | R25: Ocio | T25: =SUMIF($K$59:$L$119,R25,$O$59:$P$119) -> 0 | V25: =T25*1/$T$40 -> #DIV/0!
P26: 0 | R26: Pequeñas compras | T26: =SUMIF($K$59:$L$119,R26,$O$59:$P$119) -> 0 | V26: =T26*1/$T$40 -> #DIV/0! | X26: RESUMEN TIPO DE PAGO
P27: 0 | R27: Tasas/Impuestos | T27: =SUMIF($K$59:$L$119,R27,$O$59:$P$119) -> 0 | V27: =T27*1/$T$40 -> #DIV/0! | X27: Trajeta de débito | Z27: =SUMIF(M59:N119,"Tarjeta de débito",O59:P119)+SUMIF(N15:N39,"Tarjeta de débito",M15:M39) -> 0 | AA27: =Z27*1/$U$8 -> #DIV/0!
P28: 0 | R28: Viajes/vacaciones | T28: =SUMIF($K$59:$L$119,R28,$O$59:$P$119) -> 0 | V28: =T28*1/$T$40 -> #DIV/0! | X28: Tarjeta de crédito | Z28: =SUMIF(M59:N119,"Tarjeta de crédito",O59:P119)+SUMIF(N15:N39,"Tarjeta de crédito",M15:M39) -> 0 | AA28: =Z28*1/$U$8 -> #DIV/0!
P29: 0 | R29: Tecnología | T29: =SUMIF($K$59:$L$119,R29,$O$59:$P$119) -> 0 | V29: =T29*1/$T$40 -> #DIV/0! | X29: Efectivo | Z29: =SUMIF(M59:N119,"Efectivo",O59:P119)+SUMIF(N15:N39,"Efectivo",M15:M39) -> 0 | AA29: =Z29*1/$U$8 -> #DIV/0!
P30: 0 | R30: Reparaciones | T30: =SUMIF($K$59:$L$119,R30,$O$59:$P$119) -> 0 | V30: =T30*1/$T$40 -> #DIV/0! | X30: Transferencia | Z30: =SUMIF(M59:N119,"Transferencia",O59:P119)+SUMIF(N15:N39,"Transferencia",M15:M39) -> 0 | AA30: =Z30*1/$U$8 -> #DIV/0!
P31: 0 | R31: Salud | T31: =SUMIF($K$59:$L$119,R31,$O$59:$P$119) -> 0 | V31: =T31*1/$T$40 -> #DIV/0!
P32: 0 | R32: Higiene | T32: =SUMIF($K$59:$L$119,R32,$O$59:$P$119) -> 0 | V32: =T32*1/$T$40 -> #DIV/0! | X32: CONTROL DE DINERO
P33: 0 | R33: Cursos/Fromación/Trabajo | T33: =SUMIF($K$59:$L$119,R33,$O$59:$P$119) -> 0 | V33: =T33*1/$T$40 -> #DIV/0!
P34: 0 | R34: Mascotas | T34: =SUMIF($K$59:$L$119,R34,$O$59:$P$119) -> 0 | V34: =T34*1/$T$40 -> #DIV/0! | X34: VIRTUAL (LO QUE ANOTASTE)
P35: 0 | R35: Familia | T35: =SUMIF($K$59:$L$119,R35,$O$59:$P$119) -> 0 | V35: =T35*1/$T$40 -> #DIV/0! | X35: Resto | Z35: =W8 -> 0
D36: TOTAL INGRESOS | F36: ING ESPERADOS | H36: =SUM(G26:G35) -> 0 | P36: 0 | R36: Otros | T36: =SUMIF($K$59:$L$119,R36,$O$59:$P$119) -> 0 | V36: =T36*1/$T$40 -> #DIV/0! | X36: REAL
F37: ING REALES | H37: =SUM(H26:H35) -> 0 | P37: 0 | R37: Préstamos | T37: =SUMIF($K$59:$L$119,R37,$O$59:$P$119) -> 0 | V37: =T37*1/$T$40 -> #DIV/0! | X37: Tarjetas de débito
P38: 0 | X38: Efectivo
D39: SALDO REMANENTE (MES ANTERIOR) | P39: 0 | X39: DIFERENCIA | Z39: =(Z38+Z37)-Z35 -> 0
J40: TOTAL | L40: =SUM(L15:L39) -> 0 | M40: =SUM(M15:M39) -> 0 | R40: TOTAL | T40: =SUM(T15:U39) -> 0 | Z40: =IF(Z39<0,"Te falta dinero o anotar algo", "Te sobra dinero o anotar algo") -> Te sobra dinero o anotar algo
D42: AHORRO E INVERSIÓN | J42: TOTAL GASTOS (FIJOS + VARIABLES) | S42: =M40+O120 -> 0
D44: CONCEPTO | G44: CATEGORÍA | H44: CANTIDAD
D52: TOTAL AHORROS | H52: =SUMIF(G45:G51, "Ahorro", H45:H51) -> 0
D53: TOTAL INVERSIÓN | H53: =SUMIF(G45:G51, "Inversión", H45:H51) -> 0
...

Sheet JUNIO
D2: OBJETIVOS CUMPLIDOS | G2: RESUMEN
D3: =CTAS!L3 -> 0 | N3: JUNIO
H4: INGRESOS | J4: SALDO REMANENTE | L4: TOTAL
G5: I. DISPONIBLES | H5: =H37 -> 0 | J5: =G39 -> 0 | L5: =H5+J5 -> 0 | S5: DISPONIBLES PARA GASTOS
N6: 2026
H7: FIJOS | I7: VARIABLES | J7: AHORROS | K7: INVERSIÓN | L7: TOTAL | N7: INICIO | Q7: 46174 | S7: INGRESOS DISPONIBLES | U7: GASTOS | W7: RESTO
G8: GASTOS | H8: =M40 -> 0 | I8: =O120 -> 0 | J8: =H52 -> 0 | K8: =H53 -> 0 | L8: =SUM(H8:K8) -> 0 | N8: FINAL | Q8: 46203 | S8: =L5 -> 0 | U8: =L8 -> 0 | W8: =S8-U8 -> 0
D12: OBJETIVOS FINANCIEROS DEL MES | J12: GASTOS FIJOS | R12: GASTOS VARIABLES | X12: GASTOS TOTALES
X13: Gastos fijos | Z13: =M40 -> 0
D14: CONCEPTO | H14: ✔ | J14: CONCEPTO | L14: GASTO ESPERADO | M14: GASTO REAL | N14: METODO DE PAGO | O14: FECHA DE COBRO | P14: PAGADO | R14: CATEGORIA | T14: GASTO TOTAL POR CATEGORIA | V14: % DEL TOTAL | X14: Gastos variables | Z14: =O120 -> 0
H15: 0 | P15: 0 | R15: Transporte | T15: =SUMIF($K$59:$L$119,R15,$O$59:$P$119) -> 0 | V15: =T15*1/$T$40 -> #DIV/0! | X15: Ahorros | Z15: =H52 -> 0
H16: 0 | P16: 0 | R16: Alimentación | T16: =SUMIF($K$59:$L$119,R16,$O$59:$P$119) -> 0 | V16: =T16*1/$T$40 -> #DIV/0! | X16: Inversión | Z16: =H53 -> 0
H17: 0 | P17: 0 | R17: Restaurantes | T17: =SUMIF($K$59:$L$119,R17,$O$59:$P$119) -> 0 | V17: =T17*1/$T$40 -> #DIV/0! | X17: TOTAL | Z17: =SUM(Z13:Z16) -> 0
H18: 0 | P18: 0 | R18: Delivery | T18: =SUMIF($K$59:$L$119,R18,$O$59:$P$119) -> 0 | V18: =T18*1/$T$40 -> #DIV/0!
H19: 0 | P19: 0 | R19: Bares | T19: =SUMIF($K$59:$L$119,R19,$O$59:$P$119) -> 0 | V19: =T19*1/$T$40 -> #DIV/0!
H20: 0 | P20: 0 | R20: Ropa | T20: =SUMIF($K$59:$L$119,R20,$O$59:$P$119) -> 0 | V20: =T20*1/$T$40 -> #DIV/0!
H21: 0 | P21: 0 | R21: Belleza | T21: =SUMIF($K$59:$L$119,R21,$O$59:$P$119) -> 0 | V21: =T21*1/$T$40 -> #DIV/0!
P22: 0 | R22: Gasolina | T22: =SUMIF($K$59:$L$119,R22,$O$59:$P$119) -> 0 | V22: =T22*1/$T$40 -> #DIV/0!
D23: INGRESOS | P23: 0 | R23: Hogar | T23: =SUMIF($K$59:$L$119,R23,$O$59:$P$119) -> 0 | V23: =T23*1/$T$40 -> #DIV/0!
P24: 0 | R24: Tarjeta de crédito | T24: =SUMIF($K$59:$L$119,R24,$O$59:$P$119) -> 0 | V24: =T24*1/$T$40 -> #DIV/0!
D25: CONCEPTO | G25: CANTIDAD ESPERADA | H25: CANTIDAD RECIBIDA | P25: 0 | R25: Ocio | T25: =SUMIF($K$59:$L$119,R25,$O$59:$P$119) -> 0 | V25: =T25*1/$T$40 -> #DIV/0!
P26: 0 | R26: Pequeñas compras | T26: =SUMIF($K$59:$L$119,R26,$O$59:$P$119) -> 0 | V26: =T26*1/$T$40 -> #DIV/0! | X26: RESUMEN TIPO DE PAGO
P27: 0 | R27: Tasas/Impuestos | T27: =SUMIF($K$59:$L$119,R27,$O$59:$P$119) -> 0 | V27: =T27*1/$T$40 -> #DIV/0! | X27: Trajeta de débito | Z27: =SUMIF(M59:N119,"Tarjeta de débito",O59:P119)+SUMIF(N15:N39,"Tarjeta de débito",M15:M39) -> 0 | AA27: =Z27*1/$U$8 -> #DIV/0!
P28: 0 | R28: Viajes/vacaciones | T28: =SUMIF($K$59:$L$119,R28,$O$59:$P$119) -> 0 | V28: =T28*1/$T$40 -> #DIV/0! | X28: Tarjeta de crédito | Z28: =SUMIF(M59:N119,"Tarjeta de crédito",O59:P119)+SUMIF(N15:N39,"Tarjeta de crédito",M15:M39) -> 0 | AA28: =Z28*1/$U$8 -> #DIV/0!
P29: 0 | R29: Tecnología | T29: =SUMIF($K$59:$L$119,R29,$O$59:$P$119) -> 0 | V29: =T29*1/$T$40 -> #DIV/0! | X29: Efectivo | Z29: =SUMIF(M59:N119,"Efectivo",O59:P119)+SUMIF(N15:N39,"Efectivo",M15:M39) -> 0 | AA29: =Z29*1/$U$8 -> #DIV/0!
P30: 0 | R30: Reparaciones | T30: =SUMIF($K$59:$L$119,R30,$O$59:$P$119) -> 0 | V30: =T30*1/$T$40 -> #DIV/0! | X30: Transferencia | Z30: =SUMIF(M59:N119,"Transferencia",O59:P119)+SUMIF(N15:N39,"Transferencia",M15:M39) -> 0 | AA30: =Z30*1/$U$8 -> #DIV/0!
P31: 0 | R31: Salud | T31: =SUMIF($K$59:$L$119,R31,$O$59:$P$119) -> 0 | V31: =T31*1/$T$40 -> #DIV/0!
P32: 0 | R32: Higiene | T32: =SUMIF($K$59:$L$119,R32,$O$59:$P$119) -> 0 | V32: =T32*1/$T$40 -> #DIV/0! | X32: CONTROL DE DINERO
P33: 0 | R33: Cursos/Fromación/Trabajo | T33: =SUMIF($K$59:$L$119,R33,$O$59:$P$119) -> 0 | V33: =T33*1/$T$40 -> #DIV/0!
P34: 0 | R34: Mascotas | T34: =SUMIF($K$59:$L$119,R34,$O$59:$P$119) -> 0 | V34: =T34*1/$T$40 -> #DIV/0! | X34: VIRTUAL (LO QUE ANOTASTE)
P35: 0 | R35: Familia | T35: =SUMIF($K$59:$L$119,R35,$O$59:$P$119) -> 0 | V35: =T35*1/$T$40 -> #DIV/0! | X35: Resto | Z35: =W8 -> 0
D36: TOTAL INGRESOS | F36: ING ESPERADOS | H36: =SUM(G26:G35) -> 0 | P36: 0 | R36: Otros | T36: =SUMIF($K$59:$L$119,R36,$O$59:$P$119) -> 0 | V36: =T36*1/$T$40 -> #DIV/0! | X36: REAL
F37: ING REALES | H37: =SUM(H26:H35) -> 0 | P37: 0 | R37: Préstamos | T37: =SUMIF($K$59:$L$119,R37,$O$59:$P$119) -> 0 | V37: =T37*1/$T$40 -> #DIV/0! | X37: Tarjetas de débito
P38: 0 | X38: Efectivo
D39: SALDO REMANENTE (MES ANTERIOR) | P39: 0 | X39: DIFERENCIA | Z39: =(Z38+Z37)-Z35 -> 0
J40: TOTAL | L40: =SUM(L15:L39) -> 0 | M40: =SUM(M15:M39) -> 0 | R40: TOTAL | T40: =SUM(T15:U39) -> 0 | Z40: =IF(Z39<0,"Te falta dinero o anotar algo", "Te sobra dinero o anotar algo") -> Te sobra dinero o anotar algo
D42: AHORRO E INVERSIÓN | J42: TOTAL GASTOS (FIJOS + VARIABLES) | S42: =M40+O120 -> 0
D44: CONCEPTO | G44: CATEGORÍA | H44: CANTIDAD
D52: TOTAL AHORROS | H52: =SUMIF(G45:G51, "Ahorro", H45:H51) -> 0
D53: TOTAL INVERSIÓN | H53: =SUMIF(G45:G51, "Inversión", H45:H51) -> 0
...

Sheet JULIO
D2: OBJETIVOS CUMPLIDOS | G2: RESUMEN
D3: =CTAS!B8 -> 0 | N3: JULIO
H4: INGRESOS | J4: SALDO REMANENTE | L4: TOTAL
G5: I. DISPONIBLES | H5: =H37 -> 0 | J5: =G39 -> 0 | L5: =H5+J5 -> 0 | S5: DISPONIBLES PARA GASTOS
N6: 2026
H7: FIJOS | I7: VARIABLES | J7: AHORROS | K7: INVERSIÓN | L7: TOTAL | N7: INICIO | Q7: 46204 | S7: INGRESOS DISPONIBLES | U7: GASTOS | W7: RESTO
G8: GASTOS | H8: =M40 -> 0 | I8: =O120 -> 0 | J8: =H52 -> 0 | K8: =H53 -> 0 | L8: =SUM(H8:K8) -> 0 | N8: FINAL | Q8: 46234 | S8: =L5 -> 0 | U8: =L8 -> 0 | W8: =S8-U8 -> 0
D12: OBJETIVOS FINANCIEROS DEL MES | J12: GASTOS FIJOS | R12: GASTOS VARIABLES | X12: GASTOS TOTALES
X13: Gastos fijos | Z13: =M40 -> 0
D14: CONCEPTO | H14: ✔ | J14: CONCEPTO | L14: GASTO ESPERADO | M14: GASTO REAL | N14: METODO DE PAGO | O14: FECHA DE COBRO | P14: PAGADO | R14: CATEGORIA | T14: GASTO TOTAL POR CATEGORIA | V14: % DEL TOTAL | X14: Gastos variables | Z14: =O120 -> 0
H15: 0 | P15: 0 | R15: Transporte | T15: =SUMIF($K$59:$L$119,R15,$O$59:$P$119) -> 0 | V15: =T15*1/$T$40 -> #DIV/0! | X15: Ahorros | Z15: =H52 -> 0
H16: 0 | P16: 0 | R16: Alimentación | T16: =SUMIF($K$59:$L$119,R16,$O$59:$P$119) -> 0 | V16: =T16*1/$T$40 -> #DIV/0! | X16: Inversión | Z16: =H53 -> 0
H17: 0 | P17: 0 | R17: Restaurantes | T17: =SUMIF($K$59:$L$119,R17,$O$59:$P$119) -> 0 | V17: =T17*1/$T$40 -> #DIV/0! | X17: TOTAL | Z17: =SUM(Z13:Z16) -> 0
H18: 0 | P18: 0 | R18: Delivery | T18: =SUMIF($K$59:$L$119,R18,$O$59:$P$119) -> 0 | V18: =T18*1/$T$40 -> #DIV/0!
H19: 0 | P19: 0 | R19: Bares | T19: =SUMIF($K$59:$L$119,R19,$O$59:$P$119) -> 0 | V19: =T19*1/$T$40 -> #DIV/0!
H20: 0 | P20: 0 | R20: Ropa | T20: =SUMIF($K$59:$L$119,R20,$O$59:$P$119) -> 0 | V20: =T20*1/$T$40 -> #DIV/0!
H21: 0 | P21: 0 | R21: Belleza | T21: =SUMIF($K$59:$L$119,R21,$O$59:$P$119) -> 0 | V21: =T21*1/$T$40 -> #DIV/0!
P22: 0 | R22: Gasolina | T22: =SUMIF($K$59:$L$119,R22,$O$59:$P$119) -> 0 | V22: =T22*1/$T$40 -> #DIV/0!
D23: INGRESOS | P23: 0 | R23: Hogar | T23: =SUMIF($K$59:$L$119,R23,$O$59:$P$119) -> 0 | V23: =T23*1/$T$40 -> #DIV/0!
P24: 0 | R24: Tarjeta de crédito | T24: =SUMIF($K$59:$L$119,R24,$O$59:$P$119) -> 0 | V24: =T24*1/$T$40 -> #DIV/0!
D25: CONCEPTO | G25: CANTIDAD ESPERADA | H25: CANTIDAD RECIBIDA | P25: 0 | R25: Ocio | T25: =SUMIF($K$59:$L$119,R25,$O$59:$P$119) -> 0 | V25: =T25*1/$T$40 -> #DIV/0!
P26: 0 | R26: Pequeñas compras | T26: =SUMIF($K$59:$L$119,R26,$O$59:$P$119) -> 0 | V26: =T26*1/$T$40 -> #DIV/0! | X26: RESUMEN TIPO DE PAGO
P27: 0 | R27: Tasas/Impuestos | T27: =SUMIF($K$59:$L$119,R27,$O$59:$P$119) -> 0 | V27: =T27*1/$T$40 -> #DIV/0! | X27: Trajeta de débito | Z27: =SUMIF(M59:N119,"Tarjeta de débito",O59:P119)+SUMIF(N15:N39,"Tarjeta de débito",M15:M39) -> 0 | AA27: =Z27*1/$U$8 -> #DIV/0!
P28: 0 | R28: Viajes/vacaciones | T28: =SUMIF($K$59:$L$119,R28,$O$59:$P$119) -> 0 | V28: =T28*1/$T$40 -> #DIV/0! | X28: Tarjeta de crédito | Z28: =SUMIF(M59:N119,"Tarjeta de crédito",O59:P119)+SUMIF(N15:N39,"Tarjeta de crédito",M15:M39) -> 0 | AA28: =Z28*1/$U$8 -> #DIV/0!
P29: 0 | R29: Tecnología | T29: =SUMIF($K$59:$L$119,R29,$O$59:$P$119) -> 0 | V29: =T29*1/$T$40 -> #DIV/0! | X29: Efectivo | Z29: =SUMIF(M59:N119,"Efectivo",O59:P119)+SUMIF(N15:N39,"Efectivo",M15:M39) -> 0 | AA29: =Z29*1/$U$8 -> #DIV/0!
P30: 0 | R30: Reparaciones | T30: =SUMIF($K$59:$L$119,R30,$O$59:$P$119) -> 0 | V30: =T30*1/$T$40 -> #DIV/0! | X30: Transferencia | Z30: =SUMIF(M59:N119,"Transferencia",O59:P119)+SUMIF(N15:N39,"Transferencia",M15:M39) -> 0 | AA30: =Z30*1/$U$8 -> #DIV/0!
P31: 0 | R31: Salud | T31: =SUMIF($K$59:$L$119,R31,$O$59:$P$119) -> 0 | V31: =T31*1/$T$40 -> #DIV/0!
P32: 0 | R32: Higiene | T32: =SUMIF($K$59:$L$119,R32,$O$59:$P$119) -> 0 | V32: =T32*1/$T$40 -> #DIV/0! | X32: CONTROL DE DINERO
P33: 0 | R33: Cursos/Fromación/Trabajo | T33: =SUMIF($K$59:$L$119,R33,$O$59:$P$119) -> 0 | V33: =T33*1/$T$40 -> #DIV/0!
P34: 0 | R34: Mascotas | T34: =SUMIF($K$59:$L$119,R34,$O$59:$P$119) -> 0 | V34: =T34*1/$T$40 -> #DIV/0! | X34: VIRTUAL (LO QUE ANOTASTE)
P35: 0 | R35: Familia | T35: =SUMIF($K$59:$L$119,R35,$O$59:$P$119) -> 0 | V35: =T35*1/$T$40 -> #DIV/0! | X35: Resto | Z35: =W8 -> 0
D36: TOTAL INGRESOS | F36: ING ESPERADOS | H36: =SUM(G26:G35) -> 0 | P36: 0 | R36: Otros | T36: =SUMIF($K$59:$L$119,R36,$O$59:$P$119) -> 0 | V36: =T36*1/$T$40 -> #DIV/0! | X36: REAL
F37: ING REALES | H37: =SUM(H26:H35) -> 0 | P37: 0 | R37: Préstamos | T37: =SUMIF($K$59:$L$119,R37,$O$59:$P$119) -> 0 | V37: =T37*1/$T$40 -> #DIV/0! | X37: Tarjetas de débito
P38: 0 | X38: Efectivo
D39: SALDO REMANENTE (MES ANTERIOR) | P39: 0 | X39: DIFERENCIA | Z39: =(Z38+Z37)-Z35 -> 0
J40: TOTAL | L40: =SUM(L15:L39) -> 0 | M40: =SUM(M15:M39) -> 0 | R40: TOTAL | T40: =SUM(T15:U39) -> 0 | Z40: =IF(Z39<0,"Te falta dinero o anotar algo", "Te sobra dinero o anotar algo") -> Te sobra dinero o anotar algo
D42: AHORRO E INVERSIÓN | J42: TOTAL GASTOS (FIJOS + VARIABLES) | S42: =M40+O120 -> 0
D44: CONCEPTO | G44: CATEGORÍA | H44: CANTIDAD
D52: TOTAL AHORROS | H52: =SUMIF(G45:G51, "Ahorro", H45:H51) -> 0
D53: TOTAL INVERSIÓN | H53: =SUMIF(G45:G51, "Inversión", H45:H51) -> 0
...

Sheet AGOSTO
D2: OBJETIVOS CUMPLIDOS | G2: RESUMEN
D3: =CTAS!D8 -> 0 | N3: AGOSTO
H4: INGRESOS | J4: SALDO REMANENTE | L4: TOTAL
G5: I. DISPONIBLES | H5: =H37 -> 0 | J5: =G39 -> 0 | L5: =H5+J5 -> 0 | S5: DISPONIBLES PARA GASTOS
N6: 2026
H7: FIJOS | I7: VARIABLES | J7: AHORROS | K7: INVERSIÓN | L7: TOTAL | N7: INICIO | Q7: 46235 | S7: INGRESOS DISPONIBLES | U7: GASTOS | W7: RESTO
G8: GASTOS | H8: =M40 -> 0 | I8: =O120 -> 0 | J8: =H52 -> 0 | K8: =H53 -> 0 | L8: =SUM(H8:K8) -> 0 | N8: FINAL | Q8: 46265 | S8: =L5 -> 0 | U8: =L8 -> 0 | W8: =S8-U8 -> 0
D12: OBJETIVOS FINANCIEROS DEL MES | J12: GASTOS FIJOS | R12: GASTOS VARIABLES | X12: GASTOS TOTALES
X13: Gastos fijos | Z13: =M40 -> 0
D14: CONCEPTO | H14: ✔ | J14: CONCEPTO | L14: GASTO ESPERADO | M14: GASTO REAL | N14: METODO DE PAGO | O14: FECHA DE COBRO | P14: PAGADO | R14: CATEGORIA | T14: GASTO TOTAL POR CATEGORIA | V14: % DEL TOTAL | X14: Gastos variables | Z14: =O120 -> 0
H15: 0 | P15: 0 | R15: Transporte | T15: =SUMIF($K$59:$L$119,R15,$O$59:$P$119) -> 0 | V15: =T15*1/$T$40 -> #DIV/0! | X15: Ahorros | Z15: =H52 -> 0
H16: 0 | P16: 0 | R16: Alimentación | T16: =SUMIF($K$59:$L$119,R16,$O$59:$P$119) -> 0 | V16: =T16*1/$T$40 -> #DIV/0! | X16: Inversión | Z16: =H53 -> 0
H17: 0 | P17: 0 | R17: Restaurantes | T17: =SUMIF($K$59:$L$119,R17,$O$59:$P$119) -> 0 | V17: =T17*1/$T$40 -> #DIV/0! | X17: TOTAL | Z17: =SUM(Z13:Z16) -> 0
H18: 0 | P18: 0 | R18: Delivery | T18: =SUMIF($K$59:$L$119,R18,$O$59:$P$119) -> 0 | V18: =T18*1/$T$40 -> #DIV/0!
H19: 0 | P19: 0 | R19: Bares | T19: =SUMIF($K$59:$L$119,R19,$O$59:$P$119) -> 0 | V19: =T19*1/$T$40 -> #DIV/0!
H20: 0 | P20: 0 | R20: Ropa | T20: =SUMIF($K$59:$L$119,R20,$O$59:$P$119) -> 0 | V20: =T20*1/$T$40 -> #DIV/0!
H21: 0 | P21: 0 | R21: Belleza | T21: =SUMIF($K$59:$L$119,R21,$O$59:$P$119) -> 0 | V21: =T21*1/$T$40 -> #DIV/0!
P22: 0 | R22: Gasolina | T22: =SUMIF($K$59:$L$119,R22,$O$59:$P$119) -> 0 | V22: =T22*1/$T$40 -> #DIV/0!
D23: INGRESOS | P23: 0 | R23: Hogar | T23: =SUMIF($K$59:$L$119,R23,$O$59:$P$119) -> 0 | V23: =T23*1/$T$40 -> #DIV/0!
P24: 0 | R24: Tarjeta de crédito | T24: =SUMIF($K$59:$L$119,R24,$O$59:$P$119) -> 0 | V24: =T24*1/$T$40 -> #DIV/0!
D25: CONCEPTO | G25: CANTIDAD ESPERADA | H25: CANTIDAD RECIBIDA | P25: 0 | R25: Ocio | T25: =SUMIF($K$59:$L$119,R25,$O$59:$P$119) -> 0 | V25: =T25*1/$T$40 -> #DIV/0!
P26: 0 | R26: Pequeñas compras | T26: =SUMIF($K$59:$L$119,R26,$O$59:$P$119) -> 0 | V26: =T26*1/$T$40 -> #DIV/0! | X26: RESUMEN TIPO DE PAGO
P27: 0 | R27: Tasas/Impuestos | T27: =SUMIF($K$59:$L$119,R27,$O$59:$P$119) -> 0 | V27: =T27*1/$T$40 -> #DIV/0! | X27: Trajeta de débito | Z27: =SUMIF(M59:N119,"Tarjeta de débito",O59:P119)+SUMIF(N15:N39,"Tarjeta de débito",M15:M39) -> 0 | AA27: =Z27*1/$U$8 -> #DIV/0!
P28: 0 | R28: Viajes/vacaciones | T28: =SUMIF($K$59:$L$119,R28,$O$59:$P$119) -> 0 | V28: =T28*1/$T$40 -> #DIV/0! | X28: Tarjeta de crédito | Z28: =SUMIF(M59:N119,"Tarjeta de crédito",O59:P119)+SUMIF(N15:N39,"Tarjeta de crédito",M15:M39) -> 0 | AA28: =Z28*1/$U$8 -> #DIV/0!
P29: 0 | R29: Tecnología | T29: =SUMIF($K$59:$L$119,R29,$O$59:$P$119) -> 0 | V29: =T29*1/$T$40 -> #DIV/0! | X29: Efectivo | Z29: =SUMIF(M59:N119,"Efectivo",O59:P119)+SUMIF(N15:N39,"Efectivo",M15:M39) -> 0 | AA29: =Z29*1/$U$8 -> #DIV/0!
P30: 0 | R30: Reparaciones | T30: =SUMIF($K$59:$L$119,R30,$O$59:$P$119) -> 0 | V30: =T30*1/$T$40 -> #DIV/0! | X30: Transferencia | Z30: =SUMIF(M59:N119,"Transferencia",O59:P119)+SUMIF(N15:N39,"Transferencia",M15:M39) -> 0 | AA30: =Z30*1/$U$8 -> #DIV/0!
P31: 0 | R31: Salud | T31: =SUMIF($K$59:$L$119,R31,$O$59:$P$119) -> 0 | V31: =T31*1/$T$40 -> #DIV/0!
P32: 0 | R32: Higiene | T32: =SUMIF($K$59:$L$119,R32,$O$59:$P$119) -> 0 | V32: =T32*1/$T$40 -> #DIV/0! | X32: CONTROL DE DINERO
P33: 0 | R33: Cursos/Fromación/Trabajo | T33: =SUMIF($K$59:$L$119,R33,$O$59:$P$119) -> 0 | V33: =T33*1/$T$40 -> #DIV/0!
P34: 0 | R34: Mascotas | T34: =SUMIF($K$59:$L$119,R34,$O$59:$P$119) -> 0 | V34: =T34*1/$T$40 -> #DIV/0! | X34: VIRTUAL (LO QUE ANOTASTE)
P35: 0 | R35: Familia | T35: =SUMIF($K$59:$L$119,R35,$O$59:$P$119) -> 0 | V35: =T35*1/$T$40 -> #DIV/0! | X35: Resto | Z35: =W8 -> 0
D36: TOTAL INGRESOS | F36: ING ESPERADOS | H36: =SUM(G26:G35) -> 0 | P36: 0 | R36: Otros | T36: =SUMIF($K$59:$L$119,R36,$O$59:$P$119) -> 0 | V36: =T36*1/$T$40 -> #DIV/0! | X36: REAL
F37: ING REALES | H37: =SUM(H26:H35) -> 0 | P37: 0 | R37: Préstamos | T37: =SUMIF($K$59:$L$119,R37,$O$59:$P$119) -> 0 | V37: =T37*1/$T$40 -> #DIV/0! | X37: Tarjetas de débito
P38: 0 | X38: Efectivo
D39: SALDO REMANENTE (MES ANTERIOR) | P39: 0 | X39: DIFERENCIA | Z39: =(Z38+Z37)-Z35 -> 0
J40: TOTAL | L40: =SUM(L15:L39) -> 0 | M40: =SUM(M15:M39) -> 0 | R40: TOTAL | T40: =SUM(T15:U39) -> 0 | Z40: =IF(Z39<0,"Te falta dinero o anotar algo", "Te sobra dinero o anotar algo") -> Te sobra dinero o anotar algo
D42: AHORRO E INVERSIÓN | J42: TOTAL GASTOS (FIJOS + VARIABLES) | S42: =M40+O120 -> 0
D44: CONCEPTO | G44: CATEGORÍA | H44: CANTIDAD
D52: TOTAL AHORROS | H52: =SUMIF(G45:G51, "Ahorro", H45:H51) -> 0
D53: TOTAL INVERSIÓN | H53: =SUMIF(G45:G51, "Inversión", H45:H51) -> 0
...

Sheet SEPTIEMBRE
D2: OBJETIVOS CUMPLIDOS | G2: RESUMEN
D3: =CTAS!F8 -> 0 | N3: SEPTIEMBRE
H4: INGRESOS | J4: SALDO REMANENTE | L4: TOTAL
G5: I. DISPONIBLES | H5: =H37 -> 0 | J5: =G39 -> 0 | L5: =H5+J5 -> 0 | S5: DISPONIBLES PARA GASTOS
N6: 2026
H7: FIJOS | I7: VARIABLES | J7: AHORROS | K7: INVERSIÓN | L7: TOTAL | N7: INICIO | Q7: 46266 | S7: INGRESOS DISPONIBLES | U7: GASTOS | W7: RESTO
G8: GASTOS | H8: =M40 -> 0 | I8: =O120 -> 0 | J8: =H52 -> 0 | K8: =H53 -> 0 | L8: =SUM(H8:K8) -> 0 | N8: FINAL | Q8: 46295 | S8: =L5 -> 0 | U8: =L8 -> 0 | W8: =S8-U8 -> 0
D12: OBJETIVOS FINANCIEROS DEL MES | J12: GASTOS FIJOS | R12: GASTOS VARIABLES | X12: GASTOS TOTALES
X13: Gastos fijos | Z13: =M40 -> 0
D14: CONCEPTO | H14: ✔ | J14: CONCEPTO | L14: GASTO ESPERADO | M14: GASTO REAL | N14: METODO DE PAGO | O14: FECHA DE COBRO | P14: PAGADO | R14: CATEGORIA | T14: GASTO TOTAL POR CATEGORIA | V14: % DEL TOTAL | X14: Gastos variables | Z14: =O120 -> 0
H15: 0 | P15: 0 | R15: Transporte | T15: =SUMIF($K$59:$L$119,R15,$O$59:$P$119) -> 0 | V15: =T15*1/$T$40 -> #DIV/0! | X15: Ahorros | Z15: =H52 -> 0
H16: 0 | P16: 0 | R16: Alimentación | T16: =SUMIF($K$59:$L$119,R16,$O$59:$P$119) -> 0 | V16: =T16*1/$T$40 -> #DIV/0! | X16: Inversión | Z16: =H53 -> 0
H17: 0 | P17: 0 | R17: Restaurantes | T17: =SUMIF($K$59:$L$119,R17,$O$59:$P$119) -> 0 | V17: =T17*1/$T$40 -> #DIV/0! | X17: TOTAL | Z17: =SUM(Z13:Z16) -> 0
H18: 0 | P18: 0 | R18: Delivery | T18: =SUMIF($K$59:$L$119,R18,$O$59:$P$119) -> 0 | V18: =T18*1/$T$40 -> #DIV/0!
H19: 0 | P19: 0 | R19: Bares | T19: =SUMIF($K$59:$L$119,R19,$O$59:$P$119) -> 0 | V19: =T19*1/$T$40 -> #DIV/0!
H20: 0 | P20: 0 | R20: Ropa | T20: =SUMIF($K$59:$L$119,R20,$O$59:$P$119) -> 0 | V20: =T20*1/$T$40 -> #DIV/0!
H21: 0 | P21: 0 | R21: Belleza | T21: =SUMIF($K$59:$L$119,R21,$O$59:$P$119) -> 0 | V21: =T21*1/$T$40 -> #DIV/0!
P22: 0 | R22: Gasolina | T22: =SUMIF($K$59:$L$119,R22,$O$59:$P$119) -> 0 | V22: =T22*1/$T$40 -> #DIV/0!
D23: INGRESOS | P23: 0 | R23: Hogar | T23: =SUMIF($K$59:$L$119,R23,$O$59:$P$119) -> 0 | V23: =T23*1/$T$40 -> #DIV/0!
P24: 0 | R24: Tarjeta de crédito | T24: =SUMIF($K$59:$L$119,R24,$O$59:$P$119) -> 0 | V24: =T24*1/$T$40 -> #DIV/0!
D25: CONCEPTO | G25: CANTIDAD ESPERADA | H25: CANTIDAD RECIBIDA | P25: 0 | R25: Ocio | T25: =SUMIF($K$59:$L$119,R25,$O$59:$P$119) -> 0 | V25: =T25*1/$T$40 -> #DIV/0!
P26: 0 | R26: Pequeñas compras | T26: =SUMIF($K$59:$L$119,R26,$O$59:$P$119) -> 0 | V26: =T26*1/$T$40 -> #DIV/0! | X26: RESUMEN TIPO DE PAGO
P27: 0 | R27: Tasas/Impuestos | T27: =SUMIF($K$59:$L$119,R27,$O$59:$P$119) -> 0 | V27: =T27*1/$T$40 -> #DIV/0! | X27: Trajeta de débito | Z27: =SUMIF(M59:N119,"Tarjeta de débito",O59:P119)+SUMIF(N15:N39,"Tarjeta de débito",M15:M39) -> 0 | AA27: =Z27*1/$U$8 -> #DIV/0!
P28: 0 | R28: Viajes/vacaciones | T28: =SUMIF($K$59:$L$119,R28,$O$59:$P$119) -> 0 | V28: =T28*1/$T$40 -> #DIV/0! | X28: Tarjeta de crédito | Z28: =SUMIF(M59:N119,"Tarjeta de crédito",O59:P119)+SUMIF(N15:N39,"Tarjeta de crédito",M15:M39) -> 0 | AA28: =Z28*1/$U$8 -> #DIV/0!
P29: 0 | R29: Tecnología | T29: =SUMIF($K$59:$L$119,R29,$O$59:$P$119) -> 0 | V29: =T29*1/$T$40 -> #DIV/0! | X29: Efectivo | Z29: =SUMIF(M59:N119,"Efectivo",O59:P119)+SUMIF(N15:N39,"Efectivo",M15:M39) -> 0 | AA29: =Z29*1/$U$8 -> #DIV/0!
P30: 0 | R30: Reparaciones | T30: =SUMIF($K$59:$L$119,R30,$O$59:$P$119) -> 0 | V30: =T30*1/$T$40 -> #DIV/0! | X30: Transferencia | Z30: =SUMIF(M59:N119,"Transferencia",O59:P119)+SUMIF(N15:N39,"Transferencia",M15:M39) -> 0 | AA30: =Z30*1/$U$8 -> #DIV/0!
P31: 0 | R31: Salud | T31: =SUMIF($K$59:$L$119,R31,$O$59:$P$119) -> 0 | V31: =T31*1/$T$40 -> #DIV/0!
P32: 0 | R32: Higiene | T32: =SUMIF($K$59:$L$119,R32,$O$59:$P$119) -> 0 | V32: =T32*1/$T$40 -> #DIV/0! | X32: CONTROL DE DINERO
P33: 0 | R33: Cursos/Fromación/Trabajo | T33: =SUMIF($K$59:$L$119,R33,$O$59:$P$119) -> 0 | V33: =T33*1/$T$40 -> #DIV/0!
P34: 0 | R34: Mascotas | T34: =SUMIF($K$59:$L$119,R34,$O$59:$P$119) -> 0 | V34: =T34*1/$T$40 -> #DIV/0! | X34: VIRTUAL (LO QUE ANOTASTE)
P35: 0 | R35: Familia | T35: =SUMIF($K$59:$L$119,R35,$O$59:$P$119) -> 0 | V35: =T35*1/$T$40 -> #DIV/0! | X35: Resto | Z35: =W8 -> 0
D36: TOTAL INGRESOS | F36: ING ESPERADOS | H36: =SUM(G26:G35) -> 0 | P36: 0 | R36: Otros | T36: =SUMIF($K$59:$L$119,R36,$O$59:$P$119) -> 0 | V36: =T36*1/$T$40 -> #DIV/0! | X36: REAL
F37: ING REALES | H37: =SUM(H26:H35) -> 0 | P37: 0 | R37: Préstamos | T37: =SUMIF($K$59:$L$119,R37,$O$59:$P$119) -> 0 | V37: =T37*1/$T$40 -> #DIV/0! | X37: Tarjetas de débito
P38: 0 | X38: Efectivo
D39: SALDO REMANENTE (MES ANTERIOR) | P39: 0 | X39: DIFERENCIA | Z39: =(Z38+Z37)-Z35 -> 0
J40: TOTAL | L40: =SUM(L15:L39) -> 0 | M40: =SUM(M15:M39) -> 0 | R40: TOTAL | T40: =SUM(T15:U39) -> 0 | Z40: =IF(Z39<0,"Te falta dinero o anotar algo", "Te sobra dinero o anotar algo") -> Te sobra dinero o anotar algo
D42: AHORRO E INVERSIÓN | J42: TOTAL GASTOS (FIJOS + VARIABLES) | S42: =M40+O120 -> 0
D44: CONCEPTO | G44: CATEGORÍA | H44: CANTIDAD
D52: TOTAL AHORROS | H52: =SUMIF(G45:G51, "Ahorro", H45:H51) -> 0
D53: TOTAL INVERSIÓN | H53: =SUMIF(G45:G51, "Inversión", H45:H51) -> 0
...

Sheet OCTUBRE
D2: OBJETIVOS CUMPLIDOS | G2: RESUMEN
D3: =CTAS!H8 -> 0 | N3: OCTUBRE
H4: INGRESOS | J4: SALDO REMANENTE | L4: TOTAL
G5: I. DISPONIBLES | H5: =H37 -> 0 | J5: =G39 -> 0 | L5: =H5+J5 -> 0 | S5: DISPONIBLES PARA GASTOS
N6: 2026
H7: FIJOS | I7: VARIABLES | J7: AHORROS | K7: INVERSIÓN | L7: TOTAL | N7: INICIO | Q7: 46296 | S7: INGRESOS DISPONIBLES | U7: GASTOS | W7: RESTO
G8: GASTOS | H8: =M40 -> 0 | I8: =O120 -> 0 | J8: =H52 -> 0 | K8: =H53 -> 0 | L8: =SUM(H8:K8) -> 0 | N8: FINAL | Q8: 46326 | S8: =L5 -> 0 | U8: =L8 -> 0 | W8: =S8-U8 -> 0
D12: OBJETIVOS FINANCIEROS DEL MES | J12: GASTOS FIJOS | R12: GASTOS VARIABLES | X12: GASTOS TOTALES
X13: Gastos fijos | Z13: =M40 -> 0
D14: CONCEPTO | H14: ✔ | J14: CONCEPTO | L14: GASTO ESPERADO | M14: GASTO REAL | N14: METODO DE PAGO | O14: FECHA DE COBRO | P14: PAGADO | R14: CATEGORIA | T14: GASTO TOTAL POR CATEGORIA | V14: % DEL TOTAL | X14: Gastos variables | Z14: =O120 -> 0
