Workbook

Sheet VIEWER
A1: PROYECTO
G2: Costo obra | H2: =DB!C49+DB!H53+DB!N28 -> 100376.79
A3: Nombre | C3: Empresa X | G3: Margen | H3: 0.25
A4: Fecha inicio | C4: 45993 | G4: =IF(H3<0.15,"🔴 No tomar",IF(H3<0.22,"🟡 Justo","🟢 Rentable")) -> 🟢 Rentable
A5: Imprevistos (Sumar dias) | C5: 0 | G5: Ganancia | H5: =H2*H3 -> 25094.198
A6: Fecha fin | C6: =C4+C14 -> 46003 | G6: Precio final | H6: =H2+H5 -> 125470.99
A7: Cantidad de dias | C7: =C6-C4 -> 10
A8: Datos de la obra
A9: Tipo de obra | C9: Obra nueva
A10: Ubicación | C10: Suburbana
A11: Metros cuadrados (m²) | C11: 25
A12: Complejidad | C12: 2
A13: Nivel de terminación | C13: Alto
A14: Plazo pedido por el cliente (dias) | C14: 10
A15: Mano de obra | C15: Cantidad de personas | F15: =IF(E15/H2>0.6,"⚠️ Mano de obra > 60% del total (revisar rendimientos / precio)","") | G15: DETALLES
A16: Oficial | C16: 1 | G16: Mano de obra
A17: Medio oficial | C17: 1 | G17: Horas | H17: =DB!P28 -> 46.2
A18: Ayudante | C18: 2 | G18: Total | H18: =DB!N28 -> 20350
A19: Especialista | C19: 1 | G19: Materiales
A20: Jefe de obra | C20: 1 | G20: Cemento | H20: =DB!F36 -> 1320
A21: Equipo | C21: Dias_uso | G21: Yeso | H21: =DB!F37 -> 5346
A22: Alquier andamios | C22: 1 | G22: Placas | H22: =DB!F38 -> 15444
A23: Plataformas | C23: 1 | G23: Pintura | H23: =DB!F39 -> 1464.75
A24: Maquinaria | C24: 1 | G24: Hierro | H24: =DB!F40 -> 4413.75
A25: Seguridad | C25: 1 | G25: Material secundario 8% | H25: =DB!D42 -> 2239.08
G26: Equipo | H26: =DB!F44 -> 8600
G27: Total | H27: =SUM(H20:H26) -> 38827.58
G28: Total según terminación | H28: =DB!C49 -> 46593.096
G29: Costos indirectos
G30: Total | H30: =DB!H53 -> 33433.695

Sheet DB
A1: PARÁMETROS
A2: TipoObra_sel | B2: =VIEWER!C9 -> Obra nueva
A3: m2_sel | B3: =VIEWER!C11 -> 25
A4: Complejidad_sel | B4: =VIEWER!C12 -> 2
A5: Terminacion_sel | B5: =VIEWER!C13 -> Alto
A6: Plazo_cliente_sel | B6: =VIEWER!C14 -> 10
A9: Datos base de la obra | B9: Variables | C9: Factor
B10: Ubicación
B11: Centro | C11: 1
B12: Suburbana | C12: 1.05
B13: Campo | C13: 1.15
B14: Complejidad
B15: 1 | C15: 1
B16: 2 | C16: 1.1
B17: 3 | C17: 1.25
B18: 4 | C18: 1.4
B19: 5 | C19: 1.6
B20: Nivel de terminación
B21: Bajo | C21: 0.9
B22: Medio | C22: 1
B23: Alto | C23: 1.2
A26: Mano de obra | B26: Variables | C26: Costo_hora | D26: Horas_por_m2 | I26: Calculo_Mano_Obra
D27: Reforma | E27: Obra nueva | F27: Mantenimiento | G27: Pintura | H27: Seco | I27: Rol | J27: Costo_hora | K27: Cantidad_personas | L27: Horas | M27: Costo_total_rol | N27: Total_mano_de_obra | O27: Total_Horas | P27: Total_Horas_Ajustadas_Complejidad_y_Terminación
B28: Oficial | C28: 650 | D28: 0.45 | E28: 0.4 | F28: 0.25 | G28: 0.18 | H28: 0.35 | I28: =B28 -> Oficial | J28: =INDEX($C$28:$C$32, MATCH(I28, $B$28:$B$32, 0)) -> 650 | K28: =VIEWER!C16 -> 1 | L28: =$B$3 * INDEX($D$28:$H$32, MATCH(I28, {"Oficial";"Medio oficial";"Ayudante";"Especialista";"Jefe de obra"}, 0), MATCH($B$2, $D$27:$H$27, 0) ) * K28 -> 10 | M28: =J28*L28 -> 6500 | N28: =SUM($M$28:$M$32) -> 20350 | O28: =SUM(L28:L32) -> 35 | P28: {=(INDEX($C$15:$C$19, MATCH(B4, DB!$B$15:$B$19, 0))*(INDEX($C$21:$C$23, MATCH(VIEWER!C13, DB!$B$21:$B$23, 0))) )*O28} -> 46.2
B29: Medio oficial | C29: 520 | D29: 0.35 | E29: 0.3 | F29: 0.2 | G29: 0.15 | H29: 0.3 | I29: =B29 -> Medio oficial | J29: =INDEX($C$28:$C$32, MATCH(I29, $B$28:$B$32, 0)) -> 520 | K29: =VIEWER!C17 -> 1 | L29: =$B$3 * INDEX($D$28:$H$32, MATCH(I29, {"Oficial";"Medio oficial";"Ayudante";"Especialista";"Jefe de obra"}, 0), MATCH($B$2, $D$27:$H$27, 0) ) * K29 -> 7.5 | M29: =J29*L29 -> 3900
B30: Ayudante | C30: 420 | D30: 0.3 | E30: 0.25 | F30: 0.2 | G30: 0.12 | H30: 0.25 | I30: =B30 -> Ayudante | J30: =INDEX($C$28:$C$32, MATCH(I30, $B$28:$B$32, 0)) -> 420 | K30: =VIEWER!C18 -> 2 | L30: =$B$3 * INDEX($D$28:$H$32, MATCH(I30, {"Oficial";"Medio oficial";"Ayudante";"Especialista";"Jefe de obra"}, 0), MATCH($B$2, $D$27:$H$27, 0) ) * K30 -> 12.5 | M30: =J30*L30 -> 5250
B31: Especialista | C31: 900 | D31: 0.15 | E31: 0.12 | F31: 0.1 | G31: 0 | H31: 0.1 | I31: =B31 -> Especialista | J31: =INDEX($C$28:$C$32, MATCH(I31, $B$28:$B$32, 0)) -> 900 | K31: =VIEWER!C19 -> 1 | L31: =$B$3 * INDEX($D$28:$H$32, MATCH(I31, {"Oficial";"Medio oficial";"Ayudante";"Especialista";"Jefe de obra"}, 0), MATCH($B$2, $D$27:$H$27, 0) ) * K31 -> 3 | M31: =J31*L31 -> 2700
B32: Jefe de obra | C32: 1000 | D32: 0.1 | E32: 0.08 | F32: 0.06 | G32: 0.05 | H32: 0.07 | I32: =B32 -> Jefe de obra | J32: =INDEX($C$28:$C$32, MATCH(I32, $B$28:$B$32, 0)) -> 1000 | K32: =VIEWER!C20 -> 1 | L32: =$B$3 * INDEX($D$28:$H$32, MATCH(I32, {"Oficial";"Medio oficial";"Ayudante";"Especialista";"Jefe de obra"}, 0), MATCH($B$2, $D$27:$H$27, 0) ) * K32 -> 2 | M32: =J32*L32 -> 2000
A35: Materiales | B35: Materiales | C35: Consumo_por_m2 | D35: Precio_unitario | E35: Desperdicio_% | F35: Costo_material | G35: Total_material
B36: Cemento | C36: 0.1 | D36: 480 | E36: 0.1 | F36: =$B$3 * C36 * D36 * (1 + E36) -> 1320 | G36: =SUM(F36:F40) -> 27988.5
B37: Yeso | C37: 0.9 | D37: 220 | E37: 0.08 | F37: =$B$3 * C37 * D37 * (1 + E37) -> 5346
B38: Placas | C38: 1.1 | D38: 520 | E38: 0.08 | F38: =$B$3 * C38 * D38 * (1 + E38) -> 15444
B39: Pintura | C39: 0.18 | D39: 310 | E39: 0.05 | F39: =$B$3 * C39 * D39 * (1 + E39) -> 1464.75
B40: Hierro | C40: 3 | D40: 55 | E40: 0.07 | F40: =$B$3 * C40 * D40 * (1 + E40) -> 4413.75
C41: Estimación_% | D41: Total_sec
B42: Material secundario | C42: 0.08 | D42: =G36 *C42 -> 2239.08
B43: Equipo | C43: Costo_diario | D43: Dias_uso | E43: Costo_equipo | F43: Total_equipo
B44: Alquiler andamios | C44: 1800 | D44: =VIEWER!C22 -> 1 | E44: =C44*D44 -> 1800 | F44: =SUM(E44:E47) -> 8600
B45: Plataformas | C45: 3500 | D45: =VIEWER!C23 -> 1 | E45: =C45*D45 -> 3500
B46: Maquinaria | C46: 2500 | D46: =VIEWER!C24 -> 1 | E46: =C46*D46 -> 2500
...
